Workbook

Sheet SFBL-PB
A1: 23/10/2025 Opening Date
D2: Opening Date:23/10/25 | F2: Opening Date:30/10/25 | H2: Opening Date:20/11/25 | J2: Opening Date:25/12/25 | L2: Opening Date:01/01/26 | N2: Opening Date:15/01/26 | P2: Opening Date:29/01/26 | R2: Opening Date:05/02/26 | T2: Opening Date:12/02/26 | V2: Opening Date:26/02/26
A3: Si | B3: Project Name | C3: Matarials Name | D3: Opening kg | E3: Opening nos | F3: Opening kg | G3: Opening nos | H3: Opening kg | I3: Opening nos | J3: Opening kg | K3: Opening nos | L3: Opening kg | M3: Opening nos | N3: Opening kg | O3: Opening nos | P3: Opening kg | Q3: Opening nos | R3: Opening kg | S3: Opening nos | T3: Opening kg | U3: Opening nos | V3: Opening kg | W3: Opening nos | X3: Transfer In | Y3: Transfer out | Z3: Blance | AA3: Nos | AB3: Whight Kg
A4: 1 | B4: SFBL-PB-01 | C4: Steel shutter - various size | D4: 4309.35 | F4: 4309.35 | H4: 4309.35 | J4: 4065.35 | K4: 0 | L4: 4065.35 | M4: 0 | N4: 3665.35 | O4: 0 | P4: 3665.35 | Q4: 0 | R4: 3665.35 | S4: 0 | T4: 3665.35 | U4: 0 | V4: 3665.35 | W4: 0 | Z4: =(H4+X4)-Y4 -> 4309.35
A5: 2 | B5: SFBL-PB-01 | C5: Steel props | D5: 1928.5 | E5: 101.5 | F5: 1928.5 | G5: 101.5 | H5: 1928.5 | I5: 101.5 | J5: 1805 | K5: 95 | L5: 1805 | M5: 95 | N5: 1672 | O5: 88 | P5: 1672 | Q5: 88 | R5: 1672 | S5: 88 | T5: 1672 | U5: 88 | V5: 1672 | W5: 88 | Z5: =(H5+X5)-Y5 -> 1928.5 | AA5: =Z5/19 -> 101.5 | AB5: =Z5/AA5 -> 19
A6: 3 | B6: SFBL-PB-01 | C6: Scaffolding long | D6: -74 | E6: -2 | F6: -74 | G6: -2 | H6: -74 | I6: -2 | J6: -1295 | K6: -35 | L6: -1295 | M6: -35 | N6: -1295 | O6: -35 | P6: -1295 | Q6: -35 | R6: -1295 | S6: -35 | T6: -1295 | U6: -35 | V6: -1295 | W6: -35 | Z6: =(H6+X6)-Y6 -> -74 | AA6: =Z6/37 -> -2 | AB6: =Z6/AA6 -> 37
A7: 4 | B7: SFBL-PB-01 | C7: Scaffoding short | D7: 1946.5 | E7: 114.5 | F7: 1946.5 | G7: 114.5 | H7: 1946.5 | I7: 114.5 | J7: 1912.5 | K7: 112.5 | L7: 1912.5 | M7: 112.5 | N7: 1912.5 | O7: 112.5 | P7: 1912.5 | Q7: 112.5 | R7: 1912.5 | S7: 112.5 | T7: 1912.5 | U7: 112.5 | V7: 1912.5 | W7: 112.5 | Z7: =(H7+X7)-Y7 -> 1946.5 | AA7: =Z7/17 -> 114.5 | AB7: =Z7/AA7 -> 17
A8: 5 | B8: SFBL-PB-01 | C8: Cross bar | D8: =-11610 -> -11610 | E8: -2322 | F8: =-11610 -> -11610 | G8: -2322 | H8: =-11610 -> -11610 | I8: -2322 | J8: -11760 | K8: -2352 | L8: -11760 | M8: -2352 | N8: -11760 | O8: -2352 | P8: -11760 | Q8: -2352 | R8: -11760 | S8: -2352 | T8: -11760 | U8: -2352 | V8: -11760 | W8: -2352 | Z8: =(H8+X8)-Y8 -> -11610 | AA8: =Z8/5 -> -2322 | AB8: =Z8/AA8 -> 5
A9: 6 | B9: SFBL-PB-01 | C9: Joint pin | D9: =-190.8 -> -190.8 | E9: -318 | F9: =-190.8 -> -190.8 | G9: -318 | H9: =-190.8 -> -190.8 | I9: -318 | J9: -201 | K9: -335 | L9: -201 | M9: -335 | N9: -201 | O9: -333 | P9: -201 | Q9: -333 | R9: -201 | S9: -333 | T9: -201 | U9: -333 | V9: -201 | W9: -333 | Z9: =(H9+X9)-Y9 -> -190.8 | AA9: =Z9/0.6 -> -318 | AB9: =Z9/AA9 -> 0.6
A10: 7 | B10: SFBL-PB-01 | C10: Adjustable Base Jack | D10: 2075 | E10: 415 | F10: 2075 | G10: 415 | H10: 2075 | I10: 415 | J10: 1900 | K10: 380 | L10: 1900 | M10: 380 | N10: 1900 | O10: 380 | P10: 1900 | Q10: 380 | R10: 1900 | S10: 380 | T10: 1900 | U10: 380 | V10: 1900 | W10: 380 | Z10: =(H10+X10)-Y10 -> 2075 | AA10: =Z10/5 -> 415 | AB10: =Z10/AA10 -> 5
A11: 8 | B11: SFBL-PB-01 | C11: U head | D11: =-745 -> -745 | E11: -149 | F11: =-745 -> -745 | G11: -149 | H11: =-745 -> -745 | I11: -149 | J11: -745 | K11: -149 | L11: -745 | M11: -149 | N11: -745 | O11: -149 | P11: -745 | Q11: -149 | R11: -745 | S11: -149 | T11: -745 | U11: -149 | V11: -745 | W11: -149 | Z11: =(H11+X11)-Y11 -> -745 | AA11: =Z11/5 -> -149 | AB11: =Z11/AA11 -> 5
A12: 9 | B12: SFBL-PB-01 | C12: Base plate | D12: 82.4 | E12: 103 | F12: 82.4 | G12: 103 | H12: 82.4 | I12: 103 | J12: 82.4 | K12: 103 | L12: 82.4 | M12: 103 | N12: 82.4 | O12: 103 | P12: 82.4 | Q12: 103 | R12: 82.4 | S12: 103 | T12: 82.4 | U12: 103 | V12: 82.4 | W12: 103 | Z12: =(H12+X12)-Y12 -> 82.4 | AA12: =Z12/0.8 -> 103 | AB12: =Z12/AA12 -> 0.8
A13: 10 | B13: SFBL-PB-01 | C13: MS angle 1.5"*1.5" | D13: 105 | F13: 105 | H13: 105 | J13: 105 | K13: 0 | L13: 105 | M13: 0 | N13: 55 | O13: 0 | P13: 55 | Q13: 0 | R13: 55 | S13: 0 | T13: 55 | U13: 0 | V13: 55 | W13: 0 | Z13: =(H13+X13)-Y13 -> 105 | AA13: 0 | AB13: 0
A14: 11 | B14: SFBL-PB-01 | C14: MS angle 2"*2" | D14: 430 | F14: 430 | H14: 430 | I14: 0 | J14: 430 | K14: 0 | L14: 430 | M14: 0 | N14: 430 | O14: 0 | P14: 430 | Q14: 0 | R14: 430 | S14: 0 | T14: 430 | U14: 0 | V14: 430 | W14: 0 | Z14: =(H14+X14)-Y14 -> 430 | AA14: 0 | AB14: 0
A15: 12 | B15: SFBL-PB-01 | C15: I-joist | D15: 0 | E15: 0 | F15: 0 | G15: 0 | H15: 0 | I15: 0 | J15: 0 | K15: 0 | L15: 0 | M15: 0 | O15: 0 | Q15: 0 | S15: 0 | U15: 0 | W15: 0 | Z15: =(H15+X15)-Y15 -> 0 | AA15: 0 | AB15: 0
A16: 13 | B16: SFBL-PB-01 | C16: Ms.sheet | D16: 8559.5 | E16: 503.3 | F16: 8559.5 | G16: 503.3 | H16: 8559.5 | I16: 503.3 | J16: 7930.5 | K16: 466.5 | L16: 7930.5 | M16: 466.5 | N16: 7743.5 | O16: 455.5 | P16: 7743.5 | Q16: 455.5 | R16: 7743.5 | S16: 455.5 | T16: 7743.5 | U16: 455.5 | V16: 7743.5 | W16: 455.5 | Z16: =(H16+X16)-Y16 -> 8559.5 | AA16: =Z16/17 -> 503.5 | AB16: =Z16/AA16 -> 17
A17: 14 | B17: SFBL-PB-01 | C17: Shutter Grill | D17: 0 | F17: 0 | H17: 0 | I17: 0 | J17: 0 | K17: 0 | L17: 0 | M17: 0 | O17: 0 | Q17: 0 | S17: 0 | U17: 0 | W17: 0 | Z17: =(H17+X17)-Y17 -> 0 | AA17: =Z17/19 -> 0 | AB17: 0
A18: 15 | B18: SFBL-PB-01 | C18: Hollow box 1.5" x 1.5" | D18: 4135.3 | F18: 4135.3 | H18: 4135.3 | I18: 0 | J18: 3035.3 | K18: 0 | L18: 3035.3 | M18: 0 | N18: 1535.3 | O18: 0 | P18: 1535.3 | Q18: 0 | R18: 1535.3 | S18: 0 | T18: 1535.3 | U18: 0 | V18: 1535.3 | W18: 0 | Z18: =(H18+X18)-Y18 -> 4135.3 | AA18: 0 | AB18: 0
A19: 16 | B19: SFBL-PB-01 | C19: Hollow box 3" x 3" | D19: 3798 | F19: 3798 | H19: 3798 | I19: 0 | J19: 3798 | K19: 0 | L19: 3798 | M19: 0 | N19: 2848 | O19: 0 | P19: 2848 | Q19: 0 | R19: 2848 | S19: 0 | T19: 2848 | U19: 0 | V19: 2848 | W19: 0 | Z19: =(H19+X19)-Y19 -> 3798 | AA19: 0 | AB19: 0
A20: 17 | B20: SFBL-PB-01 | C20: MS pipe 1.5" | D20: 1450 | F20: 1450 | H20: 1450 | I20: 0 | J20: 1450 | K20: 0 | L20: 1450 | M20: 0 | N20: 1450 | O20: 0 | P20: 1450 | Q20: 0 | R20: 1450 | S20: 0 | T20: 1450 | U20: 0 | V20: 1450 | W20: 0 | Z20: =(H20+X20)-Y20 -> 1450 | AA20: 0 | AB20: 0
A21: 18 | B21: SFBL-PB-01 | C21: MS pipe 1.75” | D21: -4381.2 | F21: -4381.2 | H21: -4381.2 | I21: 0 | J21: -4481.2 | K21: 0 | L21: -4481.2 | M21: 0 | N21: -4481.2 | O21: 0 | P21: -4481.2 | Q21: 0 | R21: -4481.2 | S21: 0 | T21: -4481.2 | U21: 0 | V21: -4481.2 | W21: 0 | Z21: =(H21+X21)-Y21 -> -4381.2 | AA21: 0 | AB21: 0
A22: 19 | B22: SFBL-PB-01 | C22: MS pipe 2" | D22: 1817.35 | F22: 1817.35 | H22: 1817.35 | I22: 0 | J22: 1817.35 | K22: 0 | L22: 1817.35 | M22: 0 | N22: 1817.35 | O22: 0 | P22: 1817.35 | Q22: 0 | R22: 1817.35 | S22: 0 | T22: 1817.35 | U22: 0 | V22: 1817.35 | W22: 0 | Z22: =(H22+X22)-Y22 -> 1817.35 | AA22: 0 | AB22: 0
A23: 20 | B23: SFBL-PB-01 | C23: MS pipe 2.5" | D23: 221 | F23: 221 | H23: 221 | I23: 0 | J23: 221 | K23: 0 | L23: 221 | M23: 0 | N23: 221 | O23: 0 | P23: 221 | Q23: 0 | R23: 221 | S23: 0 | T23: 221 | U23: 0 | V23: 221 | W23: 0 | Z23: =(H23+X23)-Y23 -> 221 | AA23: 0 | AB23: 0
A24: 21 | B24: SFBL-PB-01 | C24: Thread Rod | D24: 1680 | F24: 1680 | H24: 1680 | I24: 0 | J24: 1680 | K24: 0 | L24: 1680 | M24: 0 | N24: 1680 | O24: 0 | P24: 1680 | Q24: 0 | R24: 1680 | S24: 0 | T24: 1680 | U24: 0 | V24: 1680 | W24: 0 | Z24: =(H24+X24)-Y24 -> 1680 | AA24: 0 | AB24: 0
A25: 22 | B25: SFBL-PB-01 | C25: Nut, Bolt & Washer | D25: 2560 | F25: 2260 | H25: 2260 | I25: 0 | J25: 2260 | K25: 0 | L25: 2260 | M25: 0 | N25: 2260 | O25: 0 | P25: 2260 | Q25: 0 | R25: 2260 | S25: 0 | T25: 2260 | U25: 0 | V25: 2260 | W25: 0 | Z25: =(H25+X25)-Y25 -> 2260 | AA25: 0 | AB25: 0
A26: 23 | B26: SFBL-PB-01 | C26: T bolt (Nos) | I26: 0 | K26: 0 | M26: 0 | N26: 0 | O26: 0 | P26: 0 | Z26: =(H26+X26)-Y26 -> 0 | AA26: =Z26/19 -> 0 | AB26: 0
A27: 24 | B27: SFBL-PB-01 | C27: Trun bolt (Nos) | D27: 147 | E27: 105 | F27: =G27*1.4 -> 21 | G27: 15 | H27: =I27*1.4 -> 21 | I27: 15 | K27: 0 | M27: 0 | N27: 0 | O27: 0 | P27: 0 | Z27: =(H27+X27)-Y27 -> 21 | AA27: =Z27/19 -> 1.1052632 | AB27: 0
A28: 25 | B28: SFBL-PB-01 | C28: C- clamp (Nos) | D28: 226 | E28: 565 | F28: 226 | G28: 565 | H28: 226 | I28: 565 | J28: =K28*0.4 -> 226 | K28: 565 | L28: =M28*0.4 -> 226 | M28: 565 | N28: =O28*0.4 -> 226 | O28: 565 | P28: 226 | Q28: 565 | R28: 226 | S28: 565 | T28: 226 | U28: 565 | V28: 226 | W28: 565 | Z28: =(H28+X28)-Y28 -> 226 | AA28: =Z28/19 -> 11.894737 | AB28: 0
A29: 26 | B29: SFBL-PB-01 | C29: Pikon (Nos) | E29: 5730 | G29: 5730 | I29: 5730 | K29: 5730 | M29: 5730 | N29: 0 | O29: 5730 | Q29: 5730 | S29: 5730 | U29: 5730 | W29: 5730 | Z29: =(H29+X29)-Y29 -> 0 | AA29: =Z29/19 -> 0 | AB29: 0
A30: 27 | B30: SFBL-PB-01 | C30: Swivel clamp (Nos) | K30: -88 | M30: -88 | N30: =O30*0.6 -> -64.8 | O30: -108 | Q30: -108 | S30: -108 | U30: -108 | W30: -108 | Z30: =(H30+X30)-Y30 -> 0 | AA30: =Z30/19 -> 0 | AB30: 0
A31: 31 | B31: SFBL-PB-01 | C31: Tin (Nos) | E31: 736 | G31: 736 | I31: 736 | K31: 736 | M31: 736 | N31: 0 | O31: 596 | Q31: 46 | S31: 46 | U31: 46 | W31: 46 | Z31: =(H31+X31)-Y31 -> 0 | AA31: =Z31/19 -> 0 | AB31: 0
C32: Totall | D32: =D4+D5+D7+D10+D12+D13+D14+D16+D18+D19+D20+D22+D23+D24+D25+D27+D28 -> 35470.9 | F32: =F4+F5+F7+F10+F12+F13+F14+F16+F18+F19+F20+F22+F23+F24+F25+F27+F28 -> 35044.9 | H32: =H4+H5+H7+H10+H12+H13+H14+H16+H18+H19+H20+H22+H23+H24+H25+H27+H28 -> 35044.9 | J32: =J4+J5+J7+J10+J12+J13+J14+J16+J14+J18+J19+J20+J22+J23+J24+J25+J28 -> 33148.4 | L32: =L4+L5+L7+L10+L12+L13+L14+L16+L14+L18+L19+L20+L22+L23+L24+L25+L28 -> 33148.4 | N32: =N4+N5+N7+N10+N12+N13+N14+N16+N18+N19+N20+N22+N23+N24+N25+N28 -> 29498.4 | O32: =SUM(O4:O31) -> 5053 | P32: =P4+P5+P7+P10+P12+P13+P14+P16+P18+P19+P20+P22+P23+P24+P25+P28 -> 29498.4 | R32: =R4+R5+R7+R10+R12+R13+R14+R16+R18+R19+R20+R22+R23+R24+R25+R28 -> 29498.4 | T32: =T4+T5+T7+T10+T12+T13+T14+T16+T18+T19+T20+T22+T23+T24+T25+T28 -> 29498.4 | V32: =V4+V5+V7+V10+V12+V13+V14+V16+V18+V19+V20+V22+V23+V24+V25+V28 -> 29498.4 | Z32: =(H32+X32)-Y32 -> 35044.9
N33: =N6+N8+N11+N21 -> -18281.2 | P33: =P6+P8+P9+P11+P21 -> -18482.2 | R33: =R6+R8+R9+R11+R21 -> -18482.2 | T33: =T6+T8+T9+T11+T21 -> -18482.2 | V33: =V6+V8+V9+V11+V21 -> -18482.2
N34: =SUM(N32:N33) -> 11217.2 | P34: =SUM(P32:P33) -> 11016.2 | R34: =SUM(R32:R33) -> 11016.2 | T34: =SUM(T32:T33) -> 11016.2 | V34: =SUM(V32:V33) -> 11016.2

Sheet SFBL-AD
A2: 20/11/2025 Opening Date
D3: Opening Date:23/10/25 | F3: Opening Date:Old AB+GB | H3: Opening Date:20/11/25 | J3: Opening Date:25/12/25 | L3: Opening Date:01/01/26 | N3: Opening Date:15/01/26 | P3: Opening Date:29/01/26 | R3: Opening Date:05/02/26 | T3: Opening Date:12/02/26 | V3: Opening Date:26/02/26
A4: Si | B4: Project Name | C4: Matarials Name | D4: Opening QTY | E4: Opening nos | F4: Opening QTY | G4: Opening nos | H4: Opening QTY | I4: Opening nos | J4: Opening QTY | K4: Opening nos | L4: Opening QTY | M4: Opening nos | N4: Opening QTY | O4: Opening nos | P4: Opening QTY | Q4: Opening nos | R4: Opening QTY | S4: Opening nos | T4: Opening QTY | U4: Opening nos | V4: Opening QTY | W4: Opening nos | X4: Transfer In | Y4: Transfer Out | Z4: Blance | AA4: Nos | AB4: Whight Kg
A5: 1 | B5: SFBL-Admin Building | C5: Steel shutter - various size | D5: 27213 | F5: 24780 | G5: 0 | H5: 25961 | J5: 56758 | K5: 0 | L5: 56758 | M5: 0 | N5: 56758 | O5: 0 | P5: 59297 | Q5: 0 | R5: 59297 | S5: 0 | T5: 59297 | U5: 0 | V5: 52292 | W5: 0 | X5: 0 | Y5: =T5-V5 -> 7005
A6: 2 | B6: SFBL-Admin Building | C6: Steel props | D6: 0 | F6: 3762 | G6: 198 | H6: 23199 | I6: 1221 | J6: 16188 | K6: 852 | L6: 16188 | M6: 852 | N6: 14421 | O6: 759 | P6: 13889 | Q6: 731 | R6: 13889 | S6: 731 | T6: 13889 | U6: 731 | V6: 9728 | W6: 512 | X6: 0 | Y6: =T6-V6 -> 4161 | AA6: =Z6/19 -> 0 | AB6: =Z6/AA6 -> #DIV/0!
A7: 3 | B7: SFBL-Admin Building | C7: Scaffolding long | D7: 0 | F7: 74 | G7: 0 | H7: 4625 | I7: 125 | J7: 4773 | K7: 129 | L7: 4773 | M7: 129 | N7: 4773 | O7: 129 | P7: 5642.5 | Q7: 152.5 | R7: 5642.5 | S7: 152.5 | T7: 5642.5 | U7: 152.5 | V7: 5642.5 | W7: 152.5 | X7: =T7-V7 -> 0 | Y7: =T7-V7 -> 0 | AA7: =Z7/37 -> 0 | AB7: =Z7/AA7 -> #DIV/0!
A8: 4 | B8: SFBL-Admin Building | C8: Scaffoding short | D8: 0 | F8: 0 | G8: 0 | H8: 1360 | I8: 80 | J8: 1360 | K8: 80 | L8: 1360 | M8: 80 | N8: 1360 | O8: 80 | P8: 1564 | Q8: 92 | R8: 1564 | S8: 92 | T8: 1564 | U8: 92 | V8: 1564 | W8: 92 | X8: =T8-V8 -> 0 | Y8: =T8-V8 -> 0 | AA8: =Z8/17 -> 0 | AB8: =Z8/AA8 -> #DIV/0!
A9: 5 | B9: SFBL-Admin Building | C9: Cross bar | D9: 0 | F9: 0 | G9: 0 | H9: 3010 | I9: 602 | J9: 4870 | K9: 974 | L9: 4870 | M9: 974 | N9: 4870 | O9: 974 | P9: 5655 | Q9: 1131 | R9: 5655 | S9: 1131 | T9: 5655 | U9: 1131 | V9: 5655 | W9: 1131 | X9: 0 | Y9: =T9-V9 -> 0 | AA9: =Z9/5 -> 0 | AB9: =Z9/AA9 -> #DIV/0!
A10: 6 | B10: SFBL-Admin Building | C10: Joint pin | D10: 0 | F10: 0 | G10: 0 | H10: 192 | I10: 320 | J10: 552 | K10: 920 | L10: 552 | M10: 920 | N10: 552 | O10: 920 | P10: 750 | Q10: 1250 | R10: 750 | S10: 1250 | T10: 750 | U10: 1250 | V10: 748.2 | W10: 1247 | X10: 0 | Y10: =T10-V10 -> 1.8 | AA10: =Z10/0.6 -> 0 | AB10: =Z10/AA10 -> #DIV/0!
A11: 7 | B11: SFBL-Admin Building | C11: Adjustable Base Jack | D11: 665 | F11: 665 | G11: 133 | H11: 2940 | I11: 588 | J11: 3940 | K11: 788 | L11: 3940 | M11: 788 | N11: 3940 | O11: 788 | P11: 4940 | Q11: 988 | R11: 4940 | S11: 988 | T11: 4940 | U11: 988 | V11: 4210 | W11: 842 | X11: 0 | Y11: =T11-V11 -> 730 | AA11: =Z11/5 -> 0 | AB11: =Z11/AA11 -> #DIV/0!
A12: 8 | B12: SFBL-Admin Building | C12: U head | D12: 850 | F12: 2080 | G12: 416 | H12: 4355 | I12: 871 | J12: 10155 | K12: 2031 | L12: 10155 | M12: 2031 | N12: 10155 | O12: 2031 | P12: 15985 | Q12: 3197 | R12: 15985 | S12: 3197 | T12: 15985 | U12: 3197 | V12: 15635 | W12: 3127 | X12: 0 | Y12: =T12-V12 -> 350 | AA12: =Z12/5 -> 0 | AB12: =Z12/AA12 -> #DIV/0!
A13: 9 | B13: SFBL-Admin Building | C13: Base plate | D13: 0 | F13: 0 | G13: 0 | H13: 0 | I13: 0 | J13: 944 | K13: 1180 | L13: 944 | M13: 1180 | N13: 1064 | O13: 1330 | P13: 1783.2 | Q13: 2229 | R13: 1783.2 | S13: 2229 | T13: 1783.2 | U13: 2229 | V13: 1783.2 | W13: 2229 | X13: 0 | Y13: =T13-V13 -> 0 | AA13: =Z13/0.8 -> 0 | AB13: =Z13/AA13 -> #DIV/0!
A14: 10 | B14: SFBL-Admin Building | C14: MS angle 1.5"*1.5" | D14: 0 | F14: 0 | G14: 0 | H14: 0 | I14: 0 | J14: 0 | K14: 0 | L14: 0 | M14: 0 | N14: 0 | O14: 0 | P14: 80 | Q14: 0 | R14: 80 | S14: 0 | T14: 80 | U14: 0 | V14: 80 | W14: 0 | X14: 0 | Y14: =T14-V14 -> 0 | AA14: 0 | AB14: 0
A15: 11 | B15: SFBL-Admin Building | C15: MS angle 2"*2" | D15: 1949 | F15: 2267 | G15: 0 | H15: 4349 | I15: 0 | J15: 5485 | K15: 0 | L15: 5485 | M15: 0 | N15: 5485 | O15: 0 | P15: 7129 | Q15: 0 | R15: 7129 | S15: 0 | T15: 7129 | U15: 0 | V15: 7129 | W15: 0 | X15: 0 | Y15: =T15-V15 -> 0 | AA15: 0 | AB15: 0
A16: 12 | B16: SFBL-Admin Building | C16: I-joist | D16: 0 | F16: 0 | G16: 0 | H16: 0 | I16: 0 | J16: 0 | K16: 0 | L16: 0 | M16: 0 | N16: 0 | O16: 0 | P16: 0 | Q16: 0 | S16: 0 | U16: 0 | V16: 0 | W16: 0 | X16: 0 | Y16: =T16-V16 -> 0 | AA16: 0 | AB16: 0
A17: 13 | B17: SFBL-Admin Building | C17: Ms.sheet | D17: 1666 | F17: 1666 | G17: 98 | H17: 8636 | I17: 508 | J17: 14484 | K17: 852 | L17: 14484 | M17: 852 | N17: 11934 | O17: 702 | P17: 12189 | Q17: 717 | R17: 12189 | S17: 717 | T17: 12189 | U17: 717 | V17: 12189 | W17: 717 | X17: 0 | Y17: =T17-V17 -> 0 | AA17: =Z17/17 -> 0 | AB17: =Z17/AA17 -> #DIV/0!
A18: 14 | B18: SFBL-Admin Building | C18: Shutter Grill | D18: 0 | F18: 0 | G18: 0 | H18: 0 | I18: 0 | J18: 0 | K18: 0 | L18: 0 | M18: 0 | N18: 0 | O18: 0 | P18: 0 | Q18: 0 | R18: 0 | S18: 0 | T18: 0 | U18: 0 | V18: 0 | W18: 0 | X18: 0 | Y18: =T18-V18 -> 0 | AA18: =Z18/19 -> 0 | AB18: 0
A19: 15 | B19: SFBL-Admin Building | C19: Hollow box 1.5" x 1.5" | D19: 9451 | F19: 9281 | G19: 0 | H19: 21736 | I19: 0 | J19: 28423 | K19: 0 | L19: 28423 | M19: 0 | N19: 30003 | O19: 0 | P19: 32318 | Q19: 0 | R19: 32318 | S19: 0 | T19: 32318 | U19: 0 | V19: 32318 | W19: 0 | X19: 0 | Y19: =T19-V19 -> 0 | AA19: 0 | AB19: 0
A20: 16 | B20: SFBL-Admin Building | C20: Hollow box 3" x 3" | D20: 2852 | F20: 4332 | G20: 0 | H20: 10547 | I20: 0 | J20: 11490 | K20: 0 | L20: 11490 | M20: 0 | N20: 11390 | O20: 0 | P20: 12145 | Q20: 0 | R20: 12145 | S20: 0 | T20: 12145 | U20: 0 | V20: 12145 | W20: 0 | X20: 0 | Y20: =T20-V20 -> 0 | AA20: 0 | AB20: 0
A21: 17 | B21: SFBL-Admin Building | C21: MS pipe 1.5" | D21: 0 | F21: 0 | G21: 0 | H21: 0 | I21: 0 | J21: 0 | K21: 0 | L21: 0 | M21: 0 | N21: 0 | O21: 0 | P21: 0 | Q21: 0 | S21: 0 | U21: 0 | V21: 0 | W21: 0 | X21: 0 | Y21: =T21-V21 -> 0 | AA21: 0 | AB21: 0
A22: 18 | B22: SFBL-Admin Building | C22: MS pipe 1.75” | D22: 7500 | F22: 3537 | G22: 0 | H22: 4747 | I22: 0 | J22: 12682 | K22: 0 | L22: 12682 | M22: 0 | N22: 12137 | O22: 0 | P22: 19287 | Q22: 0 | R22: 19287 | S22: 0 | T22: 19287 | U22: 0 | V22: 19287 | W22: 0 | X22: 0 | Y22: =T22-V22 -> 0 | AA22: 0 | AB22: 0
A23: 19 | B23: SFBL-Admin Building | C23: MS pipe 2" | D23: 0 | F23: 0 | G23: 0 | H23: 0 | I23: 0 | J23: 0 | K23: 0 | L23: 0 | M23: 0 | N23: 0 | O23: 0 | P23: 0 | Q23: 0 | S23: 0 | T23: 0 | U23: 0 | V23: 0 | W23: 0 | X23: 0 | Y23: =T23-V23 -> 0 | AA23: 0 | AB23: 0
A24: 20 | B24: SFBL-Admin Building | C24: MS pipe 2.5" | D24: 0 | F24: 0 | G24: 0 | H24: 0 | I24: 0 | J24: 0 | K24: 0 | L24: 0 | M24: 0 | N24: 0 | O24: 0 | P24: 0 | Q24: 0 | S24: 0 | T24: 0 | U24: 0 | V24: 0 | W24: 0 | X24: 0 | Y24: =T24-V24 -> 0 | AA24: 0 | AB24: 0
A25: 21 | B25: SFBL-Admin Building | C25: Thread Rod | D25: 0 | F25: 0 | G25: 0 | H25: 0 | I25: 0 | J25: 0 | K25: 0 | L25: 0 | M25: 0 | N25: 0 | O25: 0 | P25: 0 | Q25: 0 | S25: 0 | T25: 0 | U25: 0 | V25: 0 | W25: 0 | X25: 0 | Y25: =T25-V25 -> 0 | AA25: 0 | AB25: 0
A26: 22 | B26: SFBL-Admin Building | C26: Nut, Bolt & Washer | D26: -76 | F26: 339 | G26: 0 | H26: 339 | I26: 0 | J26: 746 | K26: 0 | L26: 746 | M26: 0 | N26: 746 | O26: 0 | P26: 746 | Q26: 0 | R26: 746 | S26: 0 | T26: 746 | U26: 0 | V26: 746 | W26: 0 | X26: 0 | Y26: =T26-V26 -> 0 | AA26: 0 | AB26: 0
A27: 23 | B27: SFBL-Admin Building | C27: T bolt (Nos) | F27: 0 | G27: 0 | H27: 0 | I27: 0 | J27: 0 | K27: 0 | L27: 0 | M27: 0 | N27: 0 | O27: 0 | P27: 0 | Q27: 0 | S27: 0 | T27: 0 | U27: 0 | V27: 0 | W27: 0 | X27: 0 | Y27: =T27-V27 -> 0 | AA27: =Z27/19 -> 0 | AB27: 0
A28: 24 | B28: SFBL-Admin Building | C28: Trun bolt (Nos) | F28: =G28*1.4 -> 350 | G28: 250 | H28: 350 | I28: 250 | J28: 0 | K28: 250 | L28: =M28*1.4 -> 350 | M28: 250 | N28: 350 | O28: 250 | P28: 350 | Q28: 250 | R28: 350 | S28: 250 | T28: 350 | U28: 250 | V28: 286 | W28: 250 | X28: 0 | Y28: =T28-V28 -> 64 | AA28: =Z28/3 -> 0 | AB28: =Z28/AA28 -> #DIV/0!
A29: 25 | B29: SFBL-Admin Building | C29: C- clamp (Nos) | F29: 0 | G29: 0 | H29: 0 | I29: 0 | J29: 0 | K29: 0 | L29: 0 | M29: 0 | N29: 0 | O29: 0 | P29: 0 | Q29: 0 | S29: 0 | T29: 0 | U29: 0 | V29: 0 | W29: 0 | X29: 0 | Y29: =T29-V29 -> 0 | AA29: =Z29/19 -> 0 | AB29: 0
A30: 26 | B30: SFBL-Admin Building | C30: Pikon (Nos) | F30: 0 | G30: 0 | H30: 0 | I30: 0 | J30: 0 | K30: 0 | L30: 0 | M30: 0 | N30: 0 | O30: 0 | P30: 0 | Q30: 0 | S30: 0 | T30: 0 | U30: 0 | V30: 0 | W30: 0 | X30: 0 | Y30: =T30-V30 -> 0 | AA30: =Z30/19 -> 0 | AB30: 0
A31: 27 | B31: SFBL-Admin Building | C31: Swivel clamp (Nos) | D31: 66 | E31: 120 | F31: 66 | G31: 120 | H31: 66 | I31: 120 | J31: 176 | K31: 320 | L31: =M31*0.6 -> 192 | M31: 320 | N31: 176 | O31: 320 | P31: 286 | Q31: 520 | R31: 286 | S31: 520 | T31: 286 | U31: 520 | V31: 0 | W31: 520 | X31: 0 | Y31: =T31-V31 -> 286 | AA31: =Z31/0.6 -> 0 | AB31: =Z31/AA31 -> #DIV/0!
A32: 31 | B32: SFBL-Admin Building | C32: Tin (Nos) | E32: 27 | G32: 27 | H32: 0 | I32: 27 | J32: 0 | K32: 27 | L32: 0 | M32: 27 | N32: 0 | O32: 27 | P32: 0 | Q32: 607 | S32: 607 | T32: 0 | U32: 607 | V32: 0 | W32: 607 | X32: 0 | Y32: =T32-V32 -> 0 | AA32: 27 | AB32: 0
C33: Totall | D33: =SUM(D5:D32) -> 52136 | F33: =SUM(F5:F32) -> 53199 | H33: =SUM(H5:H32) -> 116412 | I33: =SUM(I5:I32) -> 4712 | J33: =SUM(J5:J32) -> 173026 | K33: =SUM(K5:K32) -> 8403 | L33: =SUM(L5:L32) -> 173392 | M33: =SUM(M6:M32) -> 8403 | N33: =SUM(N5:N32) -> 170114 | O33: =SUM(O5:O32) -> 8310 | P33: =SUM(P5:P32) -> 194035.7 | Q33: =SUM(Q5:Q32) -> 11864.5 | R33: =SUM(R5:R32) -> 194035.7 | S33: =SUM(S5:S32) -> 11864.5 | T33: =SUM(T5:T32) -> 194035.7 | U33: =SUM(U5:U32) -> 11864.5 | ... W33: =SUM(W5:W32) -> 11426.5 | X33: =P33-R33 -> 0 | Y33: =T33-V33 -> 12597.8 | AA33: =SUM(AA6:AA32) -> 27
C34: Problem

Sheet SFBL-GH
A1: 20/11/2025 Opening Date
D2: Opening Date:20/11/25 | F2: Opening Date:25/12/25 | H2: Opening Date:01/01/26 | J2: Opening Date:15/01/26 | L2: Opening Date:29/01/26 | N2: Opening Date:05/02/26 | P2: Opening Date:12/02/26 | R2: Opening Date:26/02/26 | T2: All Week | U2: All Week
A3: Si | B3: Project Name | C3: Matarials Name | D3: Opening QTY | E3: Opening Nos | F3: Opening QTY | G3: Opening Nos | H3: Opening QTY | I3: Opening Nos | J3: Opening QTY | K3: Opening Nos | L3: Opening QTY | M3: Opening Nos | N3: Opening QTY | O3: Opening Nos | P3: Opening QTY | Q3: Opening Nos | R3: Opening QTY | S3: Opening Nos | T3: Transfer In | U3: Transfer Out | V3: Blance | W3: Nos | X3: Whight Kg
A4: 1 | B4: SFBL-Main Gate | C4: Steel shutter - various size | D4: 14973 | E4: 0 | F4: 14973 | G4: 0 | H4: 14973 | I4: 0 | J4: 14973 | K4: 0 | L4: 14973 | M4: 0 | N4: 14973 | O4: 0 | P4: 14973 | Q4: 0 | R4: 14973 | S4: 0 | T4: 0 | U4: 0 | V4: =(D4+T4)-U4 -> 14973 | W4: 0
A5: 2 | B5: SFBL-Main Gate | C5: Steel props | D5: 7562 | E5: =398 -> 398 | F5: 7562 | G5: =398 -> 398 | H5: 7562 | I5: =398 -> 398 | J5: 7562 | K5: =398 -> 398 | L5: 7562 | M5: =398 -> 398 | N5: 7562 | O5: =398 -> 398 | P5: 7562 | Q5: =398 -> 398 | R5: 7562 | S5: =398 -> 398 | T5: 0 | U5: 0 | V5: =(D5+T5)-U5 -> 7562 | W5: =V5/19 -> 398 | X5: =V5/W5 -> 19
A6: 3 | B6: SFBL-Main Gate | C6: Scaffolding long | D6: 2701 | E6: 73 | F6: 2701 | G6: 73 | H6: 2701 | I6: 73 | J6: 2701 | K6: 73 | L6: 2701 | M6: 73 | N6: 2701 | O6: 73 | P6: 2701 | Q6: 73 | R6: 2701 | S6: 73 | T6: 0 | U6: 0 | V6: =(D6+T6)-U6 -> 2701 | W6: =V6/37 -> 73 | X6: =V6/W6 -> 37
A7: 4 | B7: SFBL-Main Gate | C7: Scaffoding short | D7: 1836 | E7: 108 | F7: 1836 | G7: 108 | H7: 1836 | I7: 108 | J7: 1836 | K7: 108 | L7: 1836 | M7: 108 | N7: 1836 | O7: 108 | P7: 1836 | Q7: 108 | R7: 1836 | S7: 108 | T7: 0 | U7: 0 | V7: =(D7+T7)-U7 -> 1836 | W7: =V7/17 -> 108 | X7: =V7/W7 -> 17
A8: 5 | B8: SFBL-Main Gate | C8: Cross bar | D8: 605 | E8: 121 | F8: 605 | G8: 121 | H8: 605 | I8: 121 | J8: 605 | K8: 121 | L8: 605 | M8: 121 | N8: 605 | O8: 121 | P8: 605 | Q8: 121 | R8: 605 | S8: 121 | T8: 0 | U8: 0 | V8: =(D8+T8)-U8 -> 605 | W8: =V8/5 -> 121 | X8: =V8/W8 -> 5
A9: 6 | B9: SFBL-Main Gate | C9: Joint pin | D9: 297 | E9: 495 | F9: 297 | G9: 495 | H9: 297 | I9: 495 | J9: 297 | K9: 495 | L9: 297 | M9: 495 | N9: 297 | O9: 495 | P9: 297 | Q9: 495 | R9: 297 | S9: 495 | T9: 0 | U9: 0 | V9: =(D9+T9)-U9 -> 297 | W9: =V9/0.6 -> 495 | X9: =V9/W9 -> 0.6
A10: 7 | B10: SFBL-Main Gate | C10: Adjustable Base Jack | D10: 650 | E10: 130 | F10: 650 | G10: 130 | H10: 650 | I10: 130 | J10: 650 | K10: 130 | L10: 650 | M10: 130 | N10: 650 | O10: 130 | P10: 650 | Q10: 130 | R10: 650 | S10: 130 | T10: 0 | U10: 0 | V10: =(D10+T10)-U10 -> 650 | W10: =V10/5 -> 130 | X10: =V10/W10 -> 5
A11: 8 | B11: SFBL-Main Gate | C11: U head | D11: 650 | E11: 130 | F11: 650 | G11: 130 | H11: 650 | I11: 130 | J11: 650 | K11: 130 | L11: 650 | M11: 130 | N11: 650 | O11: 130 | P11: 650 | Q11: 130 | R11: 650 | S11: 130 | T11: 0 | U11: 0 | V11: =(D11+T11)-U11 -> 650 | W11: =V11/5 -> 130 | X11: =V11/W11 -> 5
A12: 9 | B12: SFBL-Main Gate | C12: Base plate | D12: 0 | E12: 0 | F12: 0 | G12: 0 | H12: 0 | I12: 0 | J12: 0 | K12: 0 | L12: 0 | M12: 0 | N12: 0 | O12: 0 | P12: 0 | Q12: 0 | R12: 0 | S12: 0 | T12: 0 | U12: 0 | V12: =(D12+T12)-U12 -> 0 | W12: 0 | X12: 0
A13: 10 | B13: SFBL-Main Gate | C13: MS angle 1.5"*1.5" | D13: 0 | E13: 0 | F13: 0 | G13: 0 | H13: 0 | I13: 0 | J13: 0 | K13: 0 | L13: 0 | M13: 0 | N13: 0 | O13: 0 | P13: 0 | Q13: 0 | R13: 0 | S13: 0 | T13: 0 | U13: 0 | V13: =(D13+T13)-U13 -> 0 | W13: 0 | X13: 0
A14: 11 | B14: SFBL-Main Gate | C14: MS angle 2"*2" | D14: 960 | E14: 0 | F14: 960 | G14: 0 | H14: 960 | I14: 0 | J14: 960 | K14: 0 | L14: 960 | M14: 0 | N14: 960 | O14: 0 | P14: 960 | Q14: 0 | R14: 960 | S14: 0 | T14: 0 | U14: 0 | V14: =(D14+T14)-U14 -> 960 | W14: 0 | X14: 0
A15: 12 | B15: SFBL-Main Gate | C15: I-joist | D15: 0 | E15: 0 | F15: 0 | G15: 0 | H15: 0 | I15: 0 | J15: 0 | K15: 0 | L15: 0 | M15: 0 | N15: 0 | O15: 0 | P15: 0 | Q15: 0 | R15: 0 | S15: 0 | T15: 0 | U15: 0 | V15: =(D15+T15)-U15 -> 0 | W15: 0 | X15: 0
A16: 13 | B16: SFBL-Main Gate | C16: Ms.sheet | D16: 3570 | E16: 210 | F16: 3570 | G16: 210 | H16: 3570 | I16: 210 | J16: 3570 | K16: 210 | L16: 3570 | M16: 210 | N16: 3570 | O16: 210 | P16: 3570 | Q16: 210 | R16: 3570 | S16: 210 | T16: 0 | U16: 0 | V16: =(D16+T16)-U16 -> 3570 | W16: =V16/17 -> 210 | X16: =V16/W16 -> 17
A17: 14 | B17: SFBL-Main Gate | C17: Shutter Grill | D17: 0 | E17: 0 | F17: 0 | G17: 0 | H17: 0 | I17: 0 | J17: 0 | K17: 0 | L17: 0 | M17: 0 | N17: 0 | O17: 0 | P17: 0 | Q17: 0 | R17: 0 | S17: 0 | T17: 0 | U17: 0 | V17: =(D17+T17)-U17 -> 0 | W17: 0 | X17: 0
A18: 15 | B18: SFBL-Main Gate | C18: Hollow box 1.5" x 1.5" | D18: 3500 | E18: 0 | F18: 3500 | G18: 0 | H18: 3500 | I18: 0 | J18: 3500 | K18: 0 | L18: 3500 | M18: 0 | N18: 3500 | O18: 0 | P18: 3500 | Q18: 0 | R18: 3500 | S18: 0 | T18: 0 | U18: 0 | V18: =(D18+T18)-U18 -> 3500 | W18: 0 | X18: 0
A19: 16 | B19: SFBL-Main Gate | C19: Hollow box 3" x 3" | D19: 2243 | E19: 0 | F19: 2243 | G19: 0 | H19: 2243 | I19: 0 | J19: 2243 | K19: 0 | L19: 2243 | M19: 0 | N19: 2243 | O19: 0 | P19: 2243 | Q19: 0 | R19: 2243 | S19: 0 | T19: 0 | U19: 0 | V19: =(D19+T19)-U19 -> 2243 | W19: 0 | X19: 0
A20: 17 | B20: SFBL-Main Gate | C20: MS pipe 1.5" | D20: 0 | E20: 0 | F20: 0 | G20: 0 | H20: 0 | I20: 0 | J20: 0 | K20: 0 | L20: 0 | M20: 0 | N20: 0 | O20: 0 | P20: 0 | Q20: 0 | R20: 0 | S20: 0 | T20: 0 | U20: 0 | V20: =(D20+T20)-U20 -> 0 | W20: 0 | X20: 0
A21: 18 | B21: SFBL-Main Gate | C21: MS pipe 1.75” | D21: 0 | E21: 0 | F21: 0 | G21: 0 | H21: 0 | I21: 0 | J21: 0 | K21: 0 | L21: 0 | M21: 0 | N21: 0 | O21: 0 | P21: 0 | Q21: 0 | R21: 0 | S21: 0 | T21: 0 | U21: 0 | V21: =(D21+T21)-U21 -> 0 | W21: 0 | X21: 0
A22: 19 | B22: SFBL-Main Gate | C22: MS pipe 2" | D22: 0 | E22: 0 | F22: 0 | G22: 0 | H22: 0 | I22: 0 | J22: 0 | K22: 0 | L22: 0 | M22: 0 | N22: 0 | O22: 0 | P22: 0 | Q22: 0 | R22: 0 | S22: 0 | T22: 0 | U22: 0 | V22: =(D22+T22)-U22 -> 0 | W22: 0 | X22: 0
A23: 20 | B23: SFBL-Main Gate | C23: MS pipe 2.5" | D23: 0 | E23: 0 | F23: 0 | G23: 0 | H23: 0 | I23: 0 | J23: 0 | K23: 0 | L23: 0 | M23: 0 | N23: 0 | O23: 0 | P23: 0 | Q23: 0 | R23: 0 | S23: 0 | T23: 0 | U23: 0 | V23: =(D23+T23)-U23 -> 0 | W23: 0 | X23: 0
A24: 21 | B24: SFBL-Main Gate | C24: Thread Rod | D24: 0 | E24: 0 | F24: 0 | G24: 0 | H24: 0 | I24: 0 | J24: 0 | K24: 0 | L24: 0 | M24: 0 | N24: 0 | O24: 0 | P24: 0 | Q24: 0 | R24: 0 | S24: 0 | T24: 0 | U24: 0 | V24: =(D24+T24)-U24 -> 0 | W24: 0 | X24: 0
A25: 22 | B25: SFBL-Main Gate | C25: Nut, Bolt & Washer | D25: 0 | E25: 0 | F25: 0 | G25: 0 | H25: 0 | I25: 0 | J25: 0 | K25: 0 | L25: 0 | M25: 0 | N25: 0 | O25: 0 | P25: 0 | Q25: 0 | R25: 0 | S25: 0 | T25: 0 | U25: 0 | V25: =(D25+T25)-U25 -> 0 | W25: 0 | X25: 0
A26: 23 | B26: SFBL-Main Gate | C26: T bolt (Nos) | D26: 0 | E26: 0 | F26: 0 | G26: 0 | H26: 0 | I26: 0 | J26: 0 | K26: 0 | L26: 0 | M26: 0 | N26: 0 | O26: 0 | P26: 0 | Q26: 0 | R26: 0 | S26: 0 | T26: 0 | U26: 0 | V26: =(D26+T26)-U26 -> 0 | W26: 0 | X26: 0
A27: 24 | B27: SFBL-Main Gate | C27: Trun bolt (Nos) | D27: 0 | E27: 0 | F27: 0 | G27: 0 | H27: 0 | I27: 0 | J27: 0 | K27: 0 | L27: 0 | M27: 0 | N27: 0 | O27: 0 | P27: 0 | Q27: 0 | R27: 0 | S27: 0 | T27: 0 | U27: 0 | V27: =(D27+T27)-U27 -> 0 | W27: 0 | X27: 0
A28: 25 | B28: SFBL-Main Gate | C28: C- clamp (Nos) | D28: 0 | E28: 0 | F28: 0 | G28: 0 | H28: 0 | I28: 0 | J28: 0 | K28: 0 | L28: 0 | M28: 0 | N28: 0 | O28: 0 | P28: 0 | Q28: 0 | R28: 0 | S28: 0 | T28: 0 | U28: 0 | V28: =(D28+T28)-U28 -> 0 | W28: 0 | X28: 0
... A31: 31 | B31: SFBL-Main Gate | C31: Tin (Nos) | D31: 0 | E31: 0 | F31: 0 | G31: 0 | H31: 0 | I31: 0 | J31: 0 | K31: 0 | L31: 0 | M31: 0 | N31: 0 | O31: 0 | P31: 0 | Q31: 0 | R31: 0 | S31: 0 | T31: 0 | U31: 0 | V31: =(D31+T31)-U31 -> 0 | W31: 0 | X31: 0
D32: =SUM(D4:D31) -> 39547 | E32: =SUM(E4:E31) -> 1665 | F32: =SUM(F4:F31) -> 39547 | G32: =SUM(G4:G31) -> 1665 | H32: =SUM(H4:H31) -> 39547 | I32: =SUM(I4:I31) -> 1665 | J32: =SUM(J4:J31) -> 39547 | K32: =SUM(K4:K31) -> 1665 | ... S32: =SUM(S4:S31) -> 1665 | T32: 0 | U32: 0 | V32: =SUM(V4:V31) -> 39547 | W32: =SUM(W4:W31) -> 1665
E33: No KG

Sheet STP
A1: 23/10/2025 Opening Date
D2: Opening Date:23/10/25 | F2: Opening Date:30/10/25 | H2: Opening Date:20/11/25 | J2: All Week | K2: All Week | L2: Stock Cheek
A3: Si | B3: Project Name | C3: Matarials Name | D3: Opening QTY | E3: Opening NOS | F3: Opening QTY | G3: Opening NOS | H3: Opening QTY | I3: Opening NOS | J3: Transfer In | K3: Transfer Out | L3: Blance | M3: Nos | N3: Whight Kg
A4: 1 | B4: SFBL-STP | C4: Steel shutter - various size | D4: 94 | E4: 0 | F4: 94 | G4: 0 | H4: 94 | I4: 0 | L4: =(H4+J4)-K4 -> 94 | N4: =L4/M4 -> #DIV/0!
A5: 2 | B5: SFBL-STP | C5: Steel props | D5: 0 | E5: 0 | F5: 0 | G5: 0 | H5: 0 | I5: 0 | L5: =(H5+J5)-K5 -> 0 | N5: =L5/M5 -> #DIV/0!
A6: 3 | B6: SFBL-STP | C6: Scaffolding long | D6: 445 | E6: 12 | F6: 445 | G6: 12 | H6: 445 | I6: 12 | L6: =(H6+J6)-K6 -> 445 | M6: =L6/37 -> 12.027027 | N6: =L6/M6 -> 37
A7: 4 | B7: SFBL-STP | C7: Scaffoding short | D7: 85 | E7: 5 | F7: 85 | G7: 5 | H7: 85 | I7: 5 | L7: =(H7+J7)-K7 -> 85 | M7: =L7/17 -> 5 | N7: =L7/M7 -> 17
A8: 5 | B8: SFBL-STP | C8: Cross bar | D8: 520 | E8: 39.5 | F8: 520 | G8: 39.5 | H8: 520 | I8: 39.5 | L8: =(H8+J8)-K8 -> 520 | M8: =L8/5 -> 104 | N8: =L8/M8 -> 5
A9: 6 | B9: SFBL-STP | C9: Joint pin | D9: 100 | E9: 165 | F9: 100 | G9: 165 | H9: 100 | I9: 165 | L9: =(H9+J9)-K9 -> 100 | M9: =L9/0.6 -> 166.66667 | N9: =L9/M9 -> 0.6
A10: 7 | B10: SFBL-STP | C10: Adjustable Base Jack | D10: 0 | E10: 0 | F10: 0 | G10: 0 | H10: 0 | I10: 0 | L10: =(H10+J10)-K10 -> 0 | N10: =L10/M10 -> #DIV/0!
A11: 8 | B11: SFBL-STP | C11: U head | D11: 28 | E11: 7 | F11: 28 | G11: 7 | H11: 28 | I11: 7 | L11: =(H11+J11)-K11 -> 28 | M11: =L11/5 -> 5.6 | N11: =L11/M11 -> 5
A12: 9 | B12: SFBL-STP | C12: Base plate | D12: 3 | E12: 2 | F12: 3 | G12: 2 | H12: 3 | I12: 2 | L12: =(H12+J12)-K12 -> 3 | M12: =L12/5 -> 0.6 | N12: =L12/M12 -> 5
A13: 10 | B13: SFBL-STP | C13: MS angle 1.5"*1.5" | D13: 550 | E13: 0 | F13: 550 | G13: 0 | H13: 550 | I13: 0 | L13: =(H13+J13)-K13 -> 550 | N13: =L13/M13 -> #DIV/0!
A14: 11 | B14: SFBL-STP | C14: MS angle 2"*2" | D14: 15 | E14: 0 | F14: 15 | G14: 0 | H14: 15 | I14: 0 | L14: =(H14+J14)-K14 -> 15 | N14: =L14/M14 -> #DIV/0!
A15: 12 | B15: SFBL-STP | C15: I-joist | D15: 0 | E15: 0 | F15: 0 | G15: 0 | H15: 0 | I15: 0 | L15: =(H15+J15)-K15 -> 0 | N15: =L15/M15 -> #DIV/0!
A16: 13 | B16: SFBL-STP | C16: Ms.sheet | D16: 48 | E16: 3 | F16: 48 | G16: 3 | H16: 48 | I16: 3 | L16: =(H16+J16)-K16 -> 48 | M16: =L16/17 -> 2.8235294 | N16: =L16/M16 -> 17
A17: 14 | B17: SFBL-STP | C17: Shutter Grill | D17: 0 | E17: 0 | F17: 0 | G17: 0 | H17: 0 | I17: 0 | L17: =(H17+J17)-K17 -> 0 | N17: =L17/M17 -> #DIV/0!
A18: 15 | B18: SFBL-STP | C18: Hollow box 1.5" x 1.5" | D18: 36 | E18: 0 | F18: 36 | G18: 0 | H18: 36 | I18: 0 | L18: =(H18+J18)-K18 -> 36 | N18: =L18/M18 -> #DIV/0!
A19: 16 | B19: SFBL-STP | C19: Hollow box 3" x 3" | D19: 92 | E19: 0 | F19: 92 | G19: 0 | H19: 92 | I19: 0 | L19: =(H19+J19)-K19 -> 92 | N19: =L19/M19 -> #DIV/0!
A20: 17 | B20: SFBL-STP | C20: MS pipe 1.5" | D20: 0 | E20: 0 | F20: 0 | G20: 0 | H20: 0 | I20: 0 | L20: =(H20+J20)-K20 -> 0 | N20: =L20/M20 -> #DIV/0!
A21: 18 | B21: SFBL-STP | C21: MS pipe 1.75” | D21: 78 | E21: 0 | F21: 78 | G21: 0 | H21: 78 | I21: 0 | L21: =(H21+J21)-K21 -> 78 | N21: =L21/M21 -> #DIV/0!
A22: 19 | B22: SFBL-STP | C22: MS pipe 2" | D22: 0 | E22: 0 | F22: 0 | G22: 0 | H22: 0 | I22: 0 | L22: =(H22+J22)-K22 -> 0 | N22: =L22/M22 -> #DIV/0!
A23: 20 | B23: SFBL-STP | C23: MS pipe 2.5" | D23: 1257 | E23: 0 | F23: 1257 | G23: 0 | H23: 1257 | I23: 0 | L23: =(H23+J23)-K23 -> 1257 | N23: =L23/M23 -> #DIV/0!
A24: 21 | B24: SFBL-STP | C24: Thread Rod | D24: 0 | E24: 0 | F24: 0 | G24: 0 | H24: 0 | I24: 0 | L24: =(H24+J24)-K24 -> 0 | N24: =L24/M24 -> #DIV/0!
A25: 22 | B25: SFBL-STP | C25: Nut, Bolt & Washer | D25: 207 | E25: 0 | F25: 207 | G25: 0 | H25: 207 | I25: 0 | L25: =(H25+J25)-K25 -> 207 | N25: =L25/M25 -> #DIV/0!
A26: 23 | B26: SFBL-STP | C26: T bolt (Nos) | D26: 0 | E26: 0 | F26: 0 | G26: 0 | H26: 0 | I26: 0 | L26: =(H26+J26)-K26 -> 0 | N26: =L26/M26 -> #DIV/0!
A27: 24 | B27: SFBL-STP | C27: Trun bolt (Nos) | D27: 0 | E27: 0 | F27: 0 | G27: 0 | H27: 0 | I27: 0 | L27: =(H27+J27)-K27 -> 0 | N27: =L27/M27 -> #DIV/0!
A28: 25 | B28: SFBL-STP | C28: C- clamp (Nos) | D28: 2 | E28: 3 | F28: 2 | G28: 3 | H28: 2 | I28: 3 | L28: =(H28+J28)-K28 -> 2 | M28: =L28/0.4 -> 5 | N28: =L28/M28 -> 0.4
A29: 26 | B29: SFBL-STP | C29: Pikon (Nos) | D29: 0 | E29: 0 | F29: 0 | G29: 0 | H29: 0 | I29: 0 | L29: =(H29+J29)-K29 -> 0 | N29: =L29/M29 -> #DIV/0!
A30: 27 | B30: SFBL-STP | C30: Swivel clamp (Nos) | D30: =E30*0.6 -> 0 | F30: =G30*0.6 -> 0 | H30: =I30*0.6 -> 0 | L30: =(H30+J30)-K30 -> 0 | N30: =L30/M30 -> #DIV/0!
A31: 31 | B31: SFBL-STP | C31: Tin (Nos) | D31: 0 | E31: 259 | F31: 0 | G31: 259 | H31: 0 | I31: 259 | L31: =(H31+J31)-K31 -> 0 | N31: =L31/M31 -> #DIV/0!
C32: Totall | D32: =SUM(D4:D31) -> 3560 | E32: =SUM(E4:E31) -> 495.5 | F32: =SUM(F4:F31) -> 3560 | G32: =SUM(G4:G31) -> 495.5 | H32: =SUM(H4:H31) -> 3560 | I32: =SUM(I4:I31) -> 495.5 | L32: =SUM(L4:L31) -> 3560

Sheet ETP
A1: 23/10/2025 Opening Date
D2: Opening Date:23/10/25 | F2: Opening Date:30/10/25 | H2: Opening Date:20/11/25 | J2: All Week | K2: All Week | L2: Stock Cheek
A3: Si | B3: Project Name | C3: Matarials Name | D3: Opening QTY | E3: Opening nos | F3: Opening QTY | G3: Opening nos | H3: Opening QTY | I3: Opening nos | J3: Transfer In | K3: Transfer Out | L3: Blance | M3: Nos | N3: Whight Kg
A4: 1 | B4: SFBL-ETP | C4: Steel shutter - various size | D4: 86 | E4: 0 | F4: 86 | G4: 0 | H4: 86 | I4: 0 | L4: =(H4+J4)-K4 -> 86 | M4: 0 | N4: =L4/M4 -> #DIV/0!
A5: 2 | B5: SFBL-ETP | C5: Steel props | D5: 0 | E5: 0 | F5: 0 | G5: 0 | H5: 0 | I5: 0 | L5: =(H5+J5)-K5 -> 0 | M5: 0 | N5: =L5/M5 -> #DIV/0!
A6: 3 | B6: SFBL-ETP | C6: Scaffolding long | D6: 444 | E6: 12 | F6: 444 | G6: 12 | H6: 444 | I6: 12 | L6: =(H6+J6)-K6 -> 444 | M6: =L6/37 -> 12 | N6: =L6/M6 -> 37
A7: 4 | B7: SFBL-ETP | C7: Scaffoding short | D7: 119 | E7: 7 | F7: 119 | G7: 7 | H7: 119 | I7: 7 | L7: =(H7+J7)-K7 -> 119 | M7: =L7/17 -> 7 | N7: =L7/M7 -> 17
A8: 5 | B8: SFBL-ETP | C8: Cross bar | D8: 390 | E8: 39 | F8: 390 | G8: 39 | H8: 390 | I8: 39 | L8: =(H8+J8)-K8 -> 390 | M8: =L8/5 -> 78 | N8: =L8/M8 -> 5
A9: 6 | B9: SFBL-ETP | C9: Joint pin | D9: 101.4 | E9: 167 | F9: 101.4 | G9: 167 | H9: 101.4 | I9: 167 | L9: =(H9+J9)-K9 -> 101.4 | M9: =L9/0.6 -> 169 | N9: =L9/M9 -> 0.6
A10: 7 | B10: SFBL-ETP | C10: Adjustable Base Jack | D10: 0 | E10: 0 | F10: 0 | G10: 0 | H10: 0 | I10: 0 | L10: =(H10+J10)-K10 -> 0 | M10: =L10/5 -> 0 | N10: =L10/M10 -> #DIV/0!
A11: 8 | B11: SFBL-ETP | C11: U head | D11: 16 | E11: 4 | F11: 16 | G11: 4 | H11: 16 | I11: 4 | L11: =(H11+J11)-K11 -> 16 | M11: =L11/5 -> 3.2 | N11: =L11/M11 -> 5
A12: 9 | B12: SFBL-ETP | C12: Base plate | D12: 2 | E12: 2 | F12: 2 | G12: 2 | H12: 2 | I12: 2 | L12: =(H12+J12)-K12 -> 2 | M12: =L12/0.8 -> 2.5 | N12: =L12/M12 -> 0.8
A13: 10 | B13: SFBL-ETP | C13: MS angle 1.5"*1.5" | D13: 550 | E13: 0 | F13: 550 | G13: 0 | H13: 550 | I13: 0 | L13: =(H13+J13)-K13 -> 550 | M13: 0 | N13: =L13/M13 -> #DIV/0!
A14: 11 | B14: SFBL-ETP | C14: MS angle 2"*2" | D14: 10 | E14: 0 | F14: 10 | G14: 0 | H14: 10 | I14: 0 | L14: =(H14+J14)-K14 -> 10 | M14: 0 | N14: =L14/M14 -> #DIV/0!
A15: 12 | B15: SFBL-ETP | C15: I-joist | D15: 0 | E15: 0 | F15: 0 | G15: 0 | H15: 0 | I15: 0 | L15: =(H15+J15)-K15 -> 0 | M15: 0 | N15: =L15/M15 -> #DIV/0!
A16: 13 | B16: SFBL-ETP | C16: Ms.sheet | D16: 48 | E16: 3 | F16: 48 | G16: 3 | H16: 48 | I16: 3 | L16: =(H16+J16)-K16 -> 48 | M16: =L16/17 -> 2.8235294 | N16: =L16/M16 -> 17
A17: 14 | B17: SFBL-ETP | C17: Shutter Grill | D17: 0 | E17: 0 | F17: 0 | G17: 0 | H17: 0 | I17: 0 | L17: =(H17+J17)-K17 -> 0 | M17: 0 | N17: =L17/M17 -> #DIV/0!
A18: 15 | B18: SFBL-ETP | C18: Hollow box 1.5" x 1.5" | D18: 709 | E18: 0 | F18: 709 | G18: 0 | H18: 709 | I18: 0 | L18: =(H18+J18)-K18 -> 709 | M18: 0 | N18: =L18/M18 -> #DIV/0!
A19: 16 | B19: SFBL-ETP | C19: Hollow box 3" x 3" | D19: 196 | E19: 0 | F19: 196 | G19: 0 | H19: 196 | I19: 0 | L19: =(H19+J19)-K19 -> 196 | M19: 0 | N19: =L19/M19 -> #DIV/0!
A20: 17 | B20: SFBL-ETP | C20: MS pipe 1.5" | D20: 0 | E20: 0 | F20: 0 | G20: 0 | H20: 0 | I20: 0 | L20: =(H20+J20)-K20 -> 0 | M20: 0 | N20: =L20/M20 -> #DIV/0!
A21: 18 | B21: SFBL-ETP | C21: MS pipe 1.75” | D21: 87 | E21: 0 | F21: 87 | G21: 0 | H21: 87 | I21: 0 | L21: =(H21+J21)-K21 -> 87 | M21: 0 | N21: =L21/M21 -> #DIV/0!
A22: 19 | B22: SFBL-ETP | C22: MS pipe 2" | D22: 0 | E22: 0 | F22: 0 | G22: 0 | H22: 0 | I22: 0 | L22: =(H22+J22)-K22 -> 0 | M22: 0 | N22: =L22/M22 -> #DIV/0!
A23: 20 | B23: SFBL-ETP | C23: MS pipe 2.5" | D23: 1256 | E23: 0 | F23: 1256 | G23: 0 | H23: 1256 | I23: 0 | L23: =(H23+J23)-K23 -> 1256 | M23: 0 | N23: =L23/M23 -> #DIV/0!
A24: 21 | B24: SFBL-ETP | C24: Thread Rod | D24: 0 | E24: 0 | F24: 0 | G24: 0 | H24: 0 | I24: 0 | L24: =(H24+J24)-K24 -> 0 | M24: 0 | N24: =L24/M24 -> #DIV/0!
A25: 22 | B25: SFBL-ETP | C25: Nut, Bolt & Washer | D25: 171 | E25: 0 | F25: 171 | G25: 0 | H25: 171 | I25: 0 | L25: =(H25+J25)-K25 -> 171 | M25: 0 | N25: =L25/M25 -> #DIV/0!
A26: 23 | B26: SFBL-ETP | C26: T bolt (Nos) | D26: 0 | E26: 0 | F26: 0 | G26: 0 | H26: 0 | I26: 0 | L26: =(H26+J26)-K26 -> 0 | M26: 0 | N26: =L26/M26 -> #DIV/0!
A27: 24 | B27: SFBL-ETP | C27: Trun bolt (Nos) | D27: 46 | E27: 34 | F27: 46 | G27: 34 | H27: 46 | I27: 34 | L27: =(H27+J27)-K27 -> 46 | M27: =L27/1.4 -> 32.857143 | N27: =L27/M27 -> 1.4
A28: 25 | B28: SFBL-ETP | C28: C- clamp (Nos) | D28: 1 | E28: 0 | F28: 1 | G28: 0 | H28: 1 | I28: 0 | L28: =(H28+J28)-K28 -> 1 | M28: 0 | N28: =L28/M28 -> #DIV/0!
A29: 26 | B29: SFBL-ETP | C29: Pikon (Nos) | D29: 0 | E29: 0 | F29: 0 | G29: 0 | H29: 0 | I29: 0 | L29: =(H29+J29)-K29 -> 0 | M29: 0 | N29: =L29/M29 -> #DIV/0!
A30: 27 | B30: SFBL-ETP | C30: Swivel clamp (Nos) | D30: 0 | E30: 0 | F30: 0 | G30: 0 | H30: 0 | I30: 0 | L30: =(H30+J30)-K30 -> 0 | M30: 0 | N30: =L30/M30 -> #DIV/0!
A31: 31 | B31: SFBL-ETP | C31: Tin (Nos) | D31: 0 | E31: 259 | F31: 0 | G31: 259 | H31: 0 | I31: 259 | L31: =(H31+J31)-K31 -> 0 | M31: 259 | N31: =L31/M31 -> 0
D32: =SUM(D4:D31) -> 4232.4 | E32: =SUM(E4:E31) -> 527 | F32: =SUM(F4:F31) -> 4232.4 | G32: =SUM(G4:G31) -> 527 | H32: =SUM(H4:H31) -> 4232.4 | I32: =SUM(I4:I31) -> 527 | K32: =SUM(K4:K31) -> 0 | L32: =SUM(L4:L31) -> 4232.4 | M32: =SUM(M4:M31) -> 566.38067
M33: =L33+M32 -> 566.38067

Sheet SETL-PB
A1: 23/10/2025 Opening Date
D2: Opening Date:23/10/25 | F2: Opening Date:30/10/25 | H2: Opening Date:20/11/25 | J2: Opening Date:25/12/25 | L2: Opening Date:01/01/26 | N2: Opening Date:15/01/26 | P2: Opening Date:29/01/26 | R2: Opening Date:05/02/26 | T2: Opening Date:12/02/26 | V2: Opening Date:26/02/26 | X2: All Week | Y2: All Week | Z2: Stock Cheek
A3: Si | B3: Project Name | C3: Matarials Name | D3: Opening QTY | E3: Opening nos | F3: Opening QTY | G3: Opening nos | H3: Opening QTY | I3: Opening nos | J3: Opening QTY | K3: Opening nos | L3: Opening QTY | M3: Opening nos | N3: Opening QTY | O3: Opening nos | P3: Opening QTY | Q3: Opening nos | R3: Opening QTY | S3: Opening nos | T3: Opening QTY | U3: Opening nos | V3: Opening QTY | W3: Opening nos | X3: Transfer In | Y3: Transfer Out | Z3: Blance | AA3: Nos | AB3: Whight Kg
A4: 1 | B4: SETL-PB | C4: Steel shutter - various size | D4: -22750.45 | E4: 0 | F4: -22750.45 | G4: 0 | H4: -22750.45 | I4: 0 | J4: -27651.45 | K4: 0 | L4: -27651.45 | M4: 0 | N4: -27651.45 | O4: 0 | P4: -27651.45 | Q4: 0 | R4: -27651.45 | S4: 0 | T4: -27651.45 | U4: 0 | V4: -27651.45 | W4: 0 | X4: no | Y4: No KG | Z4: =N4+X4-Y4 -> #VALUE!
A5: 2 | B5: SETL-PB | C5: Steel props | D5: -392 | E5: -20 | F5: -392 | G5: -20 | H5: -392 | I5: -20 | J5: -772 | K5: -40 | L5: -772 | M5: -40 | N5: -772 | O5: -40 | P5: -772 | Q5: -40 | R5: -772 | S5: -40 | T5: -772 | U5: -40 | V5: -772 | W5: -40 | Z5: =N5+X5-Y5 -> -772 | AA5: =Z5/19 -> -40.631579 | AB5: =Z5/AA5 -> 19
A6: 3 | B6: SETL-PB | C6: Scaffolding long | D6: 2442 | E6: 66 | F6: 2442 | G6: 66 | H6: 2442 | I6: 66 | J6: 1850 | K6: 50 | L6: 1850 | M6: 50 | N6: 1850 | O6: 50 | P6: 1850 | Q6: 50 | R6: 1850 | S6: 50 | T6: 1850 | U6: 50 | V6: 1850 | W6: 50 | Z6: =N6+X6-Y6 -> 1850 | AA6: =Z6/37 -> 50 | AB6: =Z6/AA6 -> 37
A7: 4 | B7: SETL-PB | C7: Scaffoding short | D7: 153 | E7: 9 | F7: 153 | G7: 9 | H7: 153 | I7: 9 | J7: 85 | K7: 5 | L7: 85 | M7: 5 | N7: 85 | O7: 5 | P7: 85 | Q7: 5 | R7: 85 | S7: 5 | T7: 85 | U7: 5 | V7: 85 | W7: 5 | Z7: =N7+X7-Y7 -> 85 | AA7: =Z7/17 -> 5 | AB7: =Z7/AA7 -> 17
A8: 5 | B8: SETL-PB | C8: Cross bar | D8: -2065 | E8: -413 | F8: -2065 | G8: -413 | H8: -2065 | I8: -413 | J8: -2065 | K8: -413 | L8: -2065 | M8: -413 | N8: -2065 | O8: -413 | P8: -2065 | Q8: -413 | R8: -2065 | S8: -413 | T8: -2065 | U8: -413 | V8: -2065 | W8: -413 | Z8: =N8+X8-Y8 -> -2065 | AA8: =Z8/5 -> -413 | AB8: =Z8/AA8 -> 5
A9: 6 | B9: SETL-PB | C9: Joint pin | D9: 1045.8 | E9: 1743 | F9: 1045.8 | G9: 1743 | H9: 1045.8 | I9: 1743 | J9: 985 | K9: 1643 | L9: 985 | M9: 1643 | N9: 985 | O9: 1643 | P9: 985 | Q9: 1643 | R9: 985 | S9: 1643 | T9: 985 | U9: 1643 | V9: 985 | W9: 1643 | Z9: =N9+X9-Y9 -> 985 | AA9: =Z9/0.6 -> 1641.6667 | AB9: =Z9/AA9 -> 0.6
A10: 7 | B10: SETL-PB | C10: Adjustable Base Jack | D10: 180 | E10: 36 | F10: 180 | G10: 36 | H10: 180 | I10: 36 | J10: 20 | K10: 4 | L10: 20 | M10: 4 | N10: 20 | O10: 4 | P10: 20 | Q10: 4 | R10: 20 | S10: 4 | T10: 20 | U10: 4 | V10: 20 | W10: 4 | Z10: =N10+X10-Y10 -> 20 | AA10: =Z10/5 -> 4 | AB10: =Z10/AA10 -> 5
A11: 8 | B11: SETL-PB | C11: U head | D11: -100 | E11: -20 | F11: -100 | G11: -20 | H11: -100 | I11: -20 | J11: -100 | K11: -20 | L11: -100 | M11: -20 | N11: -100 | O11: -20 | P11: -100 | Q11: -20 | R11: -100 | S11: -20 | T11: -100 | U11: -20 | V11: -100 | W11: -20 | Z11: =N11+X11-Y11 -> -100 | AA11: =Z11/5 -> -20 | AB11: =Z11/AA11 -> 5
A12: 9 | B12: SETL-PB | C12: Base plate | D12: 274.4 | E12: 343 | F12: 274.4 | G12: 343 | H12: 274.4 | I12: 343 | J12: 274.4 | K12: 343 | L12: 274 | M12: 343 | N12: 274 | O12: 343 | P12: 274 | Q12: 343 | R12: 274 | S12: 343 | T12: 274 | U12: 343 | V12: 274 | W12: 343 | Z12: =N12+X12-Y12 -> 274 | AA12: =Z12/0.8 -> 342.5 | AB12: =Z12/AA12 -> 0.8
A13: 10 | B13: SETL-PB | C13: MS angle 1.5"*1.5" | D13: 4467.75 | E13: 0 | F13: 4467.75 | G13: 0 | H13: 4467.75 | I13: 0 | J13: 4467.75 | K13: 0 | L13: 4467.75 | M13: 0 | N13: 4467.75 | O13: 0 | P13: 4467.75 | Q13: 0 | R13: 4467.75 | S13: 0 | T13: 4467.75 | U13: 0 | V13: 4467.75 | W13: 0 | Z13: =N13+X13-Y13 -> 4467.75 | AA13: 0 | AB13: 0
A14: 11 | B14: SETL-PB | C14: MS angle 2"*2" | D14: 7465.56 | E14: 0 | F14: 7465.56 | G14: 0 | H14: 7465.56 | I14: 0 | J14: 6997.56 | K14: 0 | L14: 6997.56 | M14: 0 | N14: 6997.56 | O14: 0 | P14: 6997.56 | Q14: 0 | R14: 6997.56 | S14: 0 | T14: 6997.56 | U14: 0 | V14: 6997.56 | W14: 0 | Z14: =N14+X14-Y14 -> 6997.56 | AA14: 0 | AB14: 0
A15: 12 | B15: SETL-PB | C15: I-joist | D15: 0 | E15: 0 | F15: 0 | G15: 0 | H15: 0 | I15: 0 | J15: 0 | K15: 0 | L15: 0 | M15: 0 | N15: 0 | O15: 0 | Q15: 0 | S15: 0 | U15: 0 | W15: 0 | Z15: =N15+X15-Y15 -> 0 | AA15: 0 | AB15: 0
A16: 13 | B16: SETL-PB | C16: Ms.sheet | D16: 10625 | E16: 625 | F16: 10625 | G16: 625 | H16: 10625 | I16: 625 | J16: 10149 | K16: 597 | L16: 10149 | M16: 597 | N16: 10149 | O16: 597 | P16: 10149 | Q16: 597 | R16: 10149 | S16: 597 | T16: 10149 | U16: 597 | V16: 10149 | W16: 597 | Z16: =N16+X16-Y16 -> 10149 | AA16: =Z16/17 -> 597 | AB16: =Z16/AA16 -> 17
A17: 14 | B17: SETL-PB | C17: Shutter Grill | D17: 18 | E17: 1 | F17: 18 | G17: 1 | H17: 18 | I17: 1 | J17: 18 | K17: 1 | L17: 18 | M17: 1 | N17: 18 | O17: 1 | P17: 18 | Q17: 1 | R17: 18 | S17: 1 | T17: 18 | U17: 1 | V17: 18 | W17: 1 | Z17: =N17+X17-Y17 -> 18 | AA17: =Z17/19 -> 0.94736842 | AB17: 0
A18: 15 | B18: SETL-PB | C18: Hollow box 1.5" x 1.5" | D18: 20800.25 | E18: 0 | F18: 20800.25 | G18: 0 | H18: 20800.25 | I18: 0 | J18: 18963.25 | K18: 0 | L18: 18963.25 | M18: 0 | N18: 18963.25 | O18: 0 | P18: 18963.25 | Q18: 0 | R18: 18963.25 | S18: 0 | T18: 18963.25 | U18: 0 | V18: 18963.25 | W18: 0 | Z18: =N18+X18-Y18 -> 18963.25 | AA18: 0 | AB18: 0
A19: 16 | B19: SETL-PB | C19: Hollow box 3" x 3" | D19: 2013 | E19: 0 | F19: 2013 | G19: 0 | H19: 2013 | I19: 0 | J19: 1713 | K19: 0 | L19: 1713 | M19: 0 | N19: 1713 | O19: 0 | P19: 1713.8 | Q19: 0 | R19: 1713.8 | S19: 0 | T19: 1713.8 | U19: 0 | V19: 1713.8 | W19: 0 | Z19: =N19+X19-Y19 -> 1713 | AA19: 0 | AB19: 0
A20: 17 | B20: SETL-PB | C20: MS pipe 1.5" | D20: 5394.48 | E20: 0 | F20: 5394.48 | G20: 0 | H20: 5394.48 | I20: 0 | J20: 4554.48 | K20: 0 | L20: 4554.48 | M20: 0 | N20: 4554.48 | O20: 0 | P20: 4554.48 | Q20: 0 | R20: 4554.48 | S20: 0 | T20: 4554.48 | U20: 0 | V20: 4554.48 | W20: 0 | Z20: =N20+X20-Y20 -> 4554.48 | AA20: 0 | AB20: 0
A21: 18 | B21: SETL-PB | C21: MS pipe 1.75” | D21: 0 | E21: 0 | F21: 0 | G21: 0 | H21: 0 | I21: 0 | J21: 0 | K21: 0 | L21: 0 | M21: 0 | N21: 0 | O21: 0 | P21: 0 | Q21: 0 | R21: 0 | S21: 0 | T21: 0 | U21: 0 | V21: 0 | W21: 0 | Z21: =N21+X21-Y21 -> 0 | AA21: 0 | AB21: 0
A22: 19 | B22: SETL-PB | C22: MS pipe 2" | D22: 0 | E22: 0 | F22: 0 | G22: 0 | H22: 0 | I22: 0 | J22: 0 | K22: 0 | L22: 0 | M22: 0 | N22: 0 | O22: 0 | P22: 0 | Q22: 0 | R22: 0 | S22: 0 | T22: 0 | U22: 0 | V22: 0 | W22: 0 | Z22: =N22+X22-Y22 -> 0 | AA22: 0 | AB22: 0
A23: 20 | B23: SETL-PB | C23: MS pipe 2.5" | D23: 1184 | E23: 0 | F23: 1184 | G23: 0 | H23: 1184 | I23: 0 | J23: 1184.2 | K23: 0 | L23: 1184.2 | M23: 0 | N23: 1184.2 | O23: 0 | P23: 1184.2 | Q23: 0 | R23: 1184.2 | S23: 0 | T23: 1184.2 | U23: 0 | V23: 1184.2 | W23: 0 | Z23: =N23+X23-Y23 -> 1184.2 | AA23: 0 | AB23: 0
A24: 21 | B24: SETL-PB | C24: Thread Rod | D24: 0 | E24: 0 | F24: 0 | G24: 0 | H24: 0 | I24: 0 | J24: 0 | K24: 0 | L24: 0 | M24: 0 | N24: 0 | O24: 0 | P24: 0 | Q24: 0 | R24: 0 | S24: 0 | T24: 0 | U24: 0 | V24: 0 | W24: 0 | Z24: =N24+X24-Y24 -> 0 | AA24: 0 | AB24: 0
A25: 22 | B25: SETL-PB | C25: Nut, Bolt & Washer | D25: 0 | E25: 0 | F25: 0 | G25: 0 | H25: 0 | I25: 0 | J25: 0 | K25: 0 | L25: 0 | M25: 0 | N25: 0 | O25: 0 | P25: 0 | Q25: 0 | R25: 0 | S25: 0 | T25: 0 | U25: 0 | V25: 0 | W25: 0 | Z25: =N25+X25-Y25 -> 0 | AA25: 0 | AB25: 0
A26: 23 | B26: SETL-PB | C26: T bolt (Nos) | D26: 0 | E26: 0 | F26: 0 | G26: 0 | H26: 0 | I26: 0 | J26: 0 | K26: 0 | L26: 0 | M26: 0 | N26: 0 | O26: 0 | P26: 0 | Q26: 0 | R26: 0 | S26: 0 | T26: 0 | U26: 0 | V26: 0 | W26: 0 | Z26: =N26+X26-Y26 -> 0 | AA26: =Z26/19 -> 0 | AB26: 0
A27: 24 | B27: SETL-PB | C27: Trun bolt (Nos) | D27: =E27*1.4 -> 200.2 | E27: 143 | F27: 200.2 | G27: 143 | H27: 200.2 | I27: 143 | J27: =K27*1.4 -> 193.2 | K27: 138 | L27: =M27*1.4 -> 193.2 | M27: 138 | N27: =O27*1.4 -> 193.2 | O27: 138 | P27: 193.2 | Q27: 138 | R27: 193.2 | S27: 138 | T27: 193.2 | U27: 138 | V27: 193.2 | W27: 138 | Z27: =N27+X27-Y27 -> 193.2 | AA27: =Z27/1.4 -> 138 | AB27: 0
A28: 25 | B28: SETL-PB | C28: C- clamp (Nos) | D28: =E28*0.4 -> 1030.8 | E28: 2577 | F28: =G28*0.4 -> 1030.8 | G28: 2577 | H28: =I28*0.4 -> 1030.8 | I28: 2577 | J28: =K28*0.4 -> 722.8 | K28: 1807 | L28: =M28*0.4 -> 722.8 | M28: 1807 | N28: =O28*0.4 -> 722.8 | O28: 1807 | P28: 722.8 | Q28: 1807 | R28: 722.8 | S28: 1807 | T28: 722.8 | U28: 1807 | V28: 722.8 | W28: 1807 | Z28: =N28+X28-Y28 -> 722.8 | AA28: =Z28/0.4 -> 1807 | AB28: 0
A29: 26 | B29: SETL-PB | C29: Pikon (Nos) | D29: 0 | E29: 0 | F29: 0 | G29: 0 | H29: 0 | I29: 0 | J29: 0 | K29: 0 | L29: 0 | M29: 0 | N29: 0 | O29: 0 | P29: 0 | Q29: 0 | R29: 0 | S29: 0 | T29: 0 | U29: 0 | V29: 0 | W29: 0 | Z29: =N29+X29-Y29 -> 0 | AA29: =Z29/19 -> 0 | AB29: 0
A30: 27 | B30: SETL-PB | C30: Swivel clamp (Nos) | D30: =E30*0.6 -> 1465.8 | E30: 2443 | F30: =G30*0.6 -> 1465.8 | G30: 2443 | H30: =I30*0.6 -> 1465.8 | I30: 2443 | J30: =K30*0.6 -> 1393.8 | K30: 2323 | L30: =M30*0.6 -> 1393.8 | M30: 2323 | N30: =O30*0.6 -> 1393.8 | O30: 2323 | P30: 1393 | Q30: 2323 | R30: 1393 | S30: 2323 | T30: 1393 | U30: 2323 | V30: 1393 | W30: 2323 | Z30: =N30+X30-Y30 -> 1393.8 | AA30: =Z30/0.6 -> 2323 | AB30: 0
A31: 31 | B31: SETL-PB | C31: Tin (Nos) | D31: 0 | E31: 363 | F31: 0 | G31: 363 | H31: 0 | I31: 363 | K31: 363 | L31: 0 | M31: 363 | N31: 0 | O31: 363 | P31: 0 | Q31: 363 | R31: 0 | S31: 363 | T31: 0 | U31: 363 | V31: 0 | W31: 363 | Z31: =N31+X31-Y31 -> 0 | AA31: 363 | AB31: 0
D32: =D6+D7+D9+D10+D12+D13+D14+D16+D17+D18+D19+D20+D23+D27+D28+D30 -> 58760.04 | E32: =SUM(E4:E31) -> 7896 | F32: =F6+F7+F9+F10+F12+F13+F14+F16+F17+F18+F19+F20+F23+F27+F28+F30 -> 58760.04 | G32: =SUM(G4:G31) -> 7896 | H32: =H6+H7+H9+H10+H12+H13+H14+H16+H17+H18+H19+H20+H23+H27+H28+H30 -> 58760.04 | I32: =SUM(I4:I31) -> 7896 | J32: =J6+J7+J9+J10+J12+J13+J14+J16+J17+J18+J19+J20+J23+J27+J28+J30 -> 53571.44 | K32: =K6+K7+K9+K10+K12+K16+K27+K28+K30+K31 -> 7273 | L32: =L6+L7+L9+L10+L12+L13+L14+L16+L17+L18+L19+L20+L23+L27+L28+L30 -> 53571.04 | M32: =M6+M7+M9+M10+M12+M16+M17+M27+M28+M30+M31 -> 7274 | N32: =N6+N7+N9+N10+N12+N13+N14+N16+N17+N18+N19+N20+N23+N27+N28+N30 -> 53571.04 | P32: =P6+P7+P9+P10+P12+P13+P14+P16+P17+P18+P19+P20+P23+P28+P30+P27 -> 53571.04 | Q32: =SUM(Q4:Q31) -> 6801 | R32: =R6+R7+R9+R10+R12+R13+R14+R16+R17+R18+R19+R20+R23+R28+R30+R27 -> 53571.04 | S32: =SUM(S4:S31) -> 6801 | T32: =T6+T7+T9+T10+T12+T13+T14+T16+T17+T18+T19+T20+T23+T28+T30+T27 -> 53571.04 | U32: =SUM(U4:U31) -> 6801 | V32: =V6+V7+V9+V10+V12+V13+V14+V16+V17+V18+V19+V20+V23+V28+V30+V27 -> 53571.04 | W32: =SUM(W4:W31) -> 6801 | Z32: =N32+O32-X32 -> 53571.04 | AA32: =SUM(AA5:AA31) -> 6798.4825
C33: Blance--- | D33: =D4+D5+D8+D11 -> -25307.45 | F33: =F4+F5+F8+F11 -> -25307.45 | N33: =N4+N5+N8+N11 -> -30588.45 | P33: =P4+P5+P8+P11 -> -30588.45 | R33: =P33 -> -30588.45 | T33: =R33 -> -30588.45 | V33: =V4+V5+V8+V11 -> -30588.45 | Y33: No KG | Z33: =Z4+Z5+Z8+Z11 -> #VALUE!
C34: Site Stock Report Blance | D34: =SUM(D32:D33) -> 33452.59 | F34: =SUM(F32:F33) -> 33452.59 | N34: =SUM(N32:N33) -> 22982.59 | P34: =SUM(P32:P33) -> 22982.59 | R34: =SUM(R32:R33) -> 22982.59 | T34: =T32+T33 -> 22982.59 | V34: =SUM(V32:V33) -> 22982.59 | Z34: =SUM(Z32:Z33) -> #VALUE!

Sheet CCKL
A1: 20/11/2025 Opening Date
D2: Opening Date:23/10/25 | F2: Opening Date:30/10/25 | H2: Opening Date:20/11/25 | J2: Opening Date:25/12/25 | L2: Opening Date:01/01/26 | N2: Opening Date:15/01/26 | P2: Opening Date:29/01/26 | R2: Opening Date:05/02/26 | T2: Opening Date:12/02/26 | V2: Opening Date:26/02/26 | X2: All Week | Y2: All Week | Z2: Stock Cheek
A3: Si | B3: Project Name | C3: Matarials Name | D3: Opening QTY | E3: Opening nos | F3: Opening QTY | G3: Opening nos | H3: Opening QTY | I3: Opening nos | J3: Opening QTY | K3: Opening nos | L3: Opening QTY | M3: Opening nos | N3: Opening QTY | O3: Opening nos | P3: Opening QTY | Q3: Opening nos | R3: Opening QTY | S3: Opening nos | T3: Opening QTY | U3: Opening nos | V3: Opening QTY | W3: Opening nos | X3: Transfer In | Y3: Transfer Out | Z3: Blance | AA3: Nos | AB3: Whight Kg
A4: 1 | B4: CCKL | C4: Steel shutter - various size | D4: 60336.4 | E4: 0 | F4: 60336.4 | H4: =61437.4 -> 61437.4 | I4: 0 | J4: 63380.4 | K4: 0 | L4: 63380.4 | M4: 0 | N4: 63380.4 | O4: 0 | P4: 63380.4 | Q4: 0 | R4: 63180.4 | S4: 0 | T4: 62680.4 | V4: 59366.4 | W4: 0 | Y4: =T4-V4 -> 3314 | Z4: =N4+X4-Y4 -> 60066.4 | AA4: =O4 -> 0
A5: 2 | B5: CCKL | C5: Steel props | D5: 53469 | E5: 2782 | F5: 53469 | G5: 2782 | H5: 53469 | I5: 2782 | J5: 53469 | K5: 2782 | L5: 53469 | M5: 2782 | N5: 52643 | O5: 2733 | P5: 52643 | Q5: 2733 | R5: 51683 | S5: 2688 | T5: 51451 | U5: 2685 | V5: 47898 | W5: 2498 | X5: =-105=problem -> #NAME? | Y5: =T5-V5 -> 3553 | Z5: =N5+X5-Y5 -> #NAME? | AA5: =O5 -> 2733 | AB5: =Z5/AA5 -> #NAME?
A6: 3 | B6: CCKL | C6: Scaffolding long | D6: 23643 | E6: 639 | F6: 23643 | G6: 639 | H6: 23643 | I6: 639 | J6: 23643 | K6: 639 | L6: 23643 | M6: 639 | N6: 23421 | O6: 633 | P6: 23421 | Q6: 633 | R6: 23310 | S6: 630 | T6: 23273 | U6: 629 | V6: 15355 | W6: 415 | Y6: =T6-V6 -> 7918 | Z6: =N6+X6-Y6 -> 15503 | AA6: =O6 -> 633 | AB6: =Z6/AA6 -> 24.491311
A7: 4 | B7: CCKL | C7: Scaffoding short | D7: 255 | E7: 15 | F7: 255 | G7: 15 | H7: 255 | I7: 15 | J7: 255 | K7: 15 | L7: 255 | M7: 15 | N7: -68 | O7: -4 | P7: -68 | Q7: -4 | R7: 0 | S7: 0 | T7: 0 | U7: 0 | V7: 0 | W7: 0 | Y7: =T7-V7 -> 0 | Z7: =N7+X7-Y7 -> -68 | AA7: =O7 -> -4 | AB7: =Z7/AA7 -> 17
A8: 5 | B8: CCKL | C8: Cross bar | D8: 9510 | E8: 1902 | F8: 9510 | G8: 1902 | H8: 9510 | I8: 1902 | J8: 9510 | K8: 1902 | L8: 9510 | M8: 1902 | N8: 9510 | O8: 1902 | P8: 9510 | Q8: 1902 | R8: 9510 | S8: 1902 | T8: 9360 | U8: 1872 | V8: 7635 | W8: 1527 | Y8: =T8-V8 -> 1725 | Z8: =N8+X8-Y8 -> 7785 | AA8: =O8 -> 1902 | AB8: =Z8/AA8 -> 4.0930599
A9: 6 | B9: CCKL | C9: Joint pin | D9: 1056.6 | E9: 1761 | F9: 1056.6 | G9: 1761 | H9: 1056.6 | I9: 1761 | J9: 1056.6 | K9: 1761 | L9: 1056.6 | M9: 1761 | N9: 1056.6 | O9: 1761 | P9: 1056.6 | Q9: 1761 | R9: 1056.6 | S9: 1761 | T9: 876 | U9: 1461 | V9: 858 | W9: 1431 | Y9: =T9-V9 -> 18 | Z9: =N9+X9-Y9 -> 1038.6 | AA9: =O9 -> 1761 | AB9: =Z9/AA9 -> 0.58977853
A10: 7 | B10: CCKL | C10: Adjustable Base Jack | D10: 480 | E10: 96 | F10: 480 | G10: 96 | H10: 480 | I10: 96 | J10: 480 | K10: 96 | L10: 480 | M10: 96 | N10: 480 | O10: 96 | P10: 480 | Q10: 96 | R10: 480 | S10: 96 | T10: 355 | U10: 71 | V10: 300 | W10: 60 | Y10: =T10-V10 -> 55 | Z10: =N10+X10-Y10 -> 425 | AA10: =O10 -> 96 | AB10: =Z10/AA10 -> 4.4270833
A11: 8 | B11: CCKL | C11: U head | D11: 10725 | E11: 2145 | F11: 10725 | G11: 2145 | H11: 11225 | I11: 2245 | J11: 11625 | K11: 2325 | L11: 11625 | M11: 2325 | N11: 11625 | O11: 2325 | P11: 11625 | Q11: 2325 | R11: 11620 | S11: 2324 | T11: 11155 | U11: 2231 | V11: 10145 | W11: 2029 | Y11: =T11-V11 -> 1010 | Z11: =N11+X11-Y11 -> 10615 | AA11: =O11 -> 2325 | AB11: =Z11/AA11 -> 4.5655914
A12: 9 | B12: CCKL | C12: Base plate | D12: 1002.4 | E12: 1253 | F12: 1002.4 | G12: 1253 | H12: 1002.4 | I12: 1253 | J12: 1002 | K12: 1253 | L12: 1002.4 | M12: 1253 | N12: 1002.4 | O12: 1253 | P12: 1002.4 | Q12: 1253 | R12: 1002.4 | S12: 1253 | T12: 998 | U12: 1248 | V12: 982 | W12: 1228 | Y12: =T12-V12 -> 16 | Z12: =N12+X12-Y12 -> 986.4 | AA12: =O12 -> 1253 | AB12: =Z12/AA12 -> 0.78723065
A13: 10 | B13: CCKL | C13: MS angle 1.5"*1.5" | D13: 8336 | E13: 0 | F13: 8336 | G13: 0 | H13: 8336 | I13: 0 | J13: 8336 | K13: 0 | L13: 8336 | M13: 0 | N13: 8336 | O13: 0 | P13: 8336 | Q13: 0 | R13: 8336 | S13: 0 | T13: 8336 | U13: 0 | V13: 8336 | W13: 0 | Y13: =T13-V13 -> 0 | Z13: =N13+X13-Y13 -> 8336 | AA13: =O13 -> 0 | AB13: 0
A14: 11 | B14: CCKL | C14: MS angle 2"*2" | D14: 8558 | E14: 0 | F14: 8558 | G14: 0 | H14: 8558 | I14: 0 | J14: 8558 | K14: 0 | L14: 8558 | M14: 0 | N14: 8558 | O14: 0 | P14: 8558 | Q14: 0 | R14: 8468 | S14: 0 | T14: 8168 | U14: 0 | V14: 7646 | W14: 0 | Y14: =T14-V14 -> 522 | Z14: =N14+X14-Y14 -> 8036 | AA14: =O14 -> 0 | AB14: 0
A15: 12 | B15: CCKL | C15: I-joist | D15: 0 | E15: 0 | F15: 0 | G15: 0 | H15: 0 | I15: 0 | J15: 0 | K15: 0 | L15: 0 | M15: 0 | N15: 0 | O15: 0 | P15: 0 | Q15: 0 | R15: 0 | S15: 0 | T15: 0 | U15: 0 | V15: 0 | W15: 0 | Y15: =T15-V15 -> 0 | Z15: =N15+X15-Y15 -> 0 | AA15: =O15 -> 0 | AB15: 0
A16: 13 | B16: CCKL | C16: Ms.sheet | D16: 20577 | E16: 1146 | F16: 20577 | G16: 1146 | H16: 20577 | I16: 1146 | J16: 20679 | K16: 1152 | L16: 20679 | M16: 1152 | N16: 20679 | O16: 1152 | P16: 20679 | Q16: 1152 | R16: 20679 | S16: 1152 | T16: 20628 | U16: 1149 | V16: 20628 | W16: 1149 | Y16: =T16-V16 -> 0 | Z16: =N16+X16-Y16 -> 20679 | AA16: =O16 -> 1152 | AB16: =Z16/AA16 -> 17.950521
A17: 14 | B17: CCKL | C17: Shutter Grill | D17: 0 | E17: 0 | F17: 0 | G17: 0 | H17: 0 | I17: 0 | J17: 0 | K17: 0 | L17: 0 | M17: 0 | N17: 0 | O17: 0 | P17: 0 | Q17: 0 | R17: 0 | S17: 0 | T17: 0 | U17: 0 | V17: 0 | W17: 0 | Y17: =T17-V17 -> 0 | Z17: =N17+X17-Y17 -> 0 | AA17: =O17 -> 0 | AB17: 0
A18: 15 | B18: CCKL | C18: Hollow box 1.5" x 1.5" | D18: 0 | E18: 0 | F18: 0 | G18: 0 | H18: 42645 | I18: 0 | J18: 42657 | K18: 0 | L18: 42657 | M18: 0 | N18: 42657 | O18: 0 | P18: 42657 | Q18: 0 | R18: 42307 | S18: 0 | T18: 40848 | U18: 0 | V18: 38268 | W18: 0 | Y18: =T18-V18 -> 2580 | Z18: =N18+X18-Y18 -> 40077 | AA18: =O18 -> 0 | AB18: 0
A19: 16 | B19: CCKL | C19: Hollow box 3" x 3" | D19: 42645 | E19: 0 | F19: 42645 | G19: 0 | H19: 22089 | I19: 0 | J19: 22706 | K19: 0 | L19: 22706 | M19: 0 | N19: 21727 | O19: 0 | P19: 21727 | Q19: 0 | R19: 19298 | S19: 0 | T19: 18898 | U19: 0 | V19: 18018 | W19: 0 | Y19: =T19-V19 -> 880 | Z19: =N19+X19-Y19 -> 20847 | AA19: =O19 -> 0 | AB19: 0
A20: 17 | B20: CCKL | C20: MS pipe 1.5" | D20: 21459 | E20: 0 | F20: 21459 | G20: 0 | H20: 0 | I20: 0 | J20: 0 | K20: 0 | L20: 0 | M20: 0 | N20: 0 | O20: 0 | P20: 0 | Q20: 0 | R20: 0 | S20: 0 | T20: 0 | U20: 0 | V20: 0 | W20: 0 | Y20: =T20-V20 -> 0 | Z20: =N20+X20-Y20 -> 0 | AA20: =O20 -> 0 | AB20: 0
A21: 18 | B21: CCKL | C21: MS pipe 1.75” | D21: 11900 | E21: 0 | F21: 11900 | G21: 0 | H21: 12468 | I21: 0 | J21: 12878 | K21: 0 | L21: 12878 | M21: 0 | N21: 12878 | O21: 0 | P21: 12878 | Q21: 0 | R21: 12558 | S21: 0 | T21: 12358 | U21: 0 | V21: 12358 | W21: 0 | Y21: =T21-V21 -> 0 | Z21: =N21+X21-Y21 -> 12878 | AA21: =O21 -> 0 | AB21: 0
A22: 19 | B22: CCKL | C22: MS pipe 3" | D22: 0 | E22: 0 | F22: 0 | G22: 0 | H22: 470 | I22: 0 | J22: 470 | K22: 0 | L22: 470 | M22: 0 | N22: 470 | O22: 0 | P22: 470 | Q22: 0 | R22: 470 | S22: 0 | T22: 470 | U22: 0 | V22: 470 | W22: 0 | Y22: =T22-V22 -> 0 | Z22: =N22+X22-Y22 -> 470 | AA22: =O22 -> 0 | AB22: 0
A23: 20 | B23: CCKL | C23: MS pipe 2.5" | D23: 470 | E23: 0 | F23: 470 | G23: 0 | H23: 0 | I23: 0 | J23: 0 | K23: 0 | L23: 0 | M23: 0 | N23: 0 | O23: 0 | P23: 0 | Q23: 0 | R23: 0 | S23: 0 | T23: 0 | U23: 0 | V23: 0 | W23: 0 | Y23: =T23-V23 -> 0 | Z23: =N23+X23-Y23 -> 0 | AA23: =O23 -> 0 | AB23: 0
A24: 21 | B24: CCKL | C24: Thread Rod | D24: 0 | E24: 0 | F24: 0 | G24: 0 | H24: 0 | I24: 0 | J24: 0 | K24: 0 | L24: 0 | M24: 0 | N24: 0 | O24: 0 | P24: 0 | Q24: 0 | R24: 0 | S24: 0 | T24: 0 | U24: 0 | V24: 0 | W24: 0 | Y24: =T24-V24 -> 0 | Z24: =N24+X24-Y24 -> 0 | AA24: =O24 -> 0 | AB24: 0
A25: 22 | B25: CCKL | C25: Nut, Bolt & Washer | D25: 2622 | E25: 0 | F25: 2622 | G25: 0 | H25: 2622 | I25: 0 | J25: 2622 | K25: 0 | L25: 2622 | M25: 0 | N25: 2622 | O25: 0 | P25: 2622 | Q25: 0 | R25: 2622 | S25: 0 | T25: 2622 | U25: 0 | V25: 2602 | W25: 0 | Y25: =T25-V25 -> 20 | Z25: =N25+X25-Y25 -> 2602 | AA25: =O25 -> 0 | AB25: 0
A26: 23 | B26: CCKL | C26: T bolt (Nos) | D26: 0 | E26: 0 | F26: 0 | G26: 0 | H26: 0 | I26: 0 | J26: 0 | K26: 0 | L26: 0 | M26: 0 | N26: 0 | O26: 0 | P26: 0 | Q26: 0 | R26: 0 | S26: 0 | T26: 0 | U26: 0 | V26: 0 | W26: 0 | Y26: =T26-V26 -> 0 | Z26: =N26+X26-Y26 -> 0 | AA26: =O26 -> 0 | AB26: 0
A27: 24 | B27: CCKL | C27: Trun bolt (Nos) | D27: =E27*1.4 -> 315 | E27: 225 | F27: =G27*1.4 -> 315 | G27: 225 | H27: 303.75 | I27: 225 | J27: 303.75 | K27: 225 | L27: 303.75 | M27: 225 | N27: 303.75 | O27: 225 | P27: 303.75 | Q27: 225 | R27: 303.75 | S27: 225 | T27: 297 | U27: 225 | V27: 297 | W27: 225 | Y27: =T27-V27 -> 0 | Z27: =N27+X27-Y27 -> 303.75 | AA27: =O27 -> 225 | AB27: 0
A28: 25 | B28: CCKL | C28: C- clamp (Nos) | D28: 0 | E28: 0 | F28: 0 | G28: 0 | H28: 0 | I28: 0 | J28: 0 | K28: 0 | L28: 0 | M28: 0 | N28: 0 | O28: 0 | P28: 0 | Q28: 0 | R28: 0 | S28: 0 | T28: 0 | U28: 0 | V28: 0 | W28: 0 | Y28: =T28-V28 -> 0 | Z28: =N28+X28-Y28 -> 0 | AA28: =O28 -> 0 | AB28: 0
